Workbook

Sheet שער
B2: פירוט טכני וכתב כמויות
B8: 2026-10-28
B12: נחלת יצחק 34 ת"א | טל- 0505241244
H13: spacer
F14: 18

Sheet מקרא והנחיות
B1: מקרא ותוכן עניינים
A2: פרק | B2: שם הפרק | F2: עמוד
A3: 1 | B3: פירוק והריסה | F3: 4
A4: 2 | B4: בנייה ומחיצות פנים | F4: 5
A5: 3 | B5: אינסטלציה ותברואה | F5: 6
A6: 4 | B6: חשמל והכנות תקשורת | F6: 7
A7: 5 | B7: הכנות רצפה והגבהות | F7: 8
A8: 6 | B8: איטום | F8: 9
A9: 7 | B9: דלתות פנים | F9: 10
A10: 8 | B10: ריצוף וחיפוי אושי־אושי | F10: 11
A11: 9 | B11: תקרות והנמכות | F11: 13
A12: 10 | B12: צבע וגמרים דקורטיביים | F12: 14
A13: 11 | B13: נגרות אושי־אושי | F13: 15
A14: 12 | B14: מסגרות אושי־אושי | F14: 17
... A22: 20 | B22: אביזרי נגישות | F22: 26
H23: spacer
B24: מקרא והנחיות — המשך
A25: פרק | B25: שם הפרק | F25: עמוד
A26: 21 | B26: שילוט ומיתוג | F26: 27
A27: 22 | B27: ריהוט וישיבה | F27: 28
H28: spacer
H29: spacer
B30: הנחיות והערות כלליות לקבלן
A31: 1. יש להגיש הצעה לפי הסעיפים והתכולות שבמסמך הפרויקט. יש להעביר לבירור אי־התאמה, גבול תכולה לא ברור או פרט חסר לפני ביצוע העבודה הנוגעת להם.
A32: 2. אספקה, התקנה, תשתית וחיבור בידי קבלנים או ספקים שונים יפורטו בנפרד. אין להסיק אחריות רק מהופעת שם ספק או מהסימון קיים.
A33: 3. מפרטי הרשת שנקבעו בשורות נשמרים. רק פרטי סניף ובחירות שנותרו פתוחות יושלמו לפי מסמכי הפרויקט וההכרעות המאושרים; אין למלא מחלוקת מערך של סניף קודם ללא אישור.
A34: 4. לכל רכיב תכולת תמחור אחת. אספקה או עבודה המופיעות בפרק נפרד יוחרגו ממחיר הפריט שבו היו עלולות להיכלל שוב.
A35: 5. תכניות ופרטים החלים על ההצעה: {רשימת מסמכים ומהדורות לפרויקט}. פרטי הקבלן, חתימה וחותמת יושלמו בעותק ההצעה.
H36: spacer

Sheet _BOQ_META
A1: BOQ_WORKBOOK | B1: 4 | C1: contractor | D1: f971a04a-e247-46b2-8780-bc2c94895d90 | E1: 8c264356-3144-4600-a0dd-99e491db6035 | F1: oshi_oshi | G1: ["89cf1821-72b3-4c89-91dc-dda7acdc2f13","cf61fba7-00ad-4d66-b23a-f20511104b42","0821a825-0557-4b30-bd61-a657a755cdce","f8e394a4-d615-44e1-9ee5-d336cee69506","b282e2b0-fec5-4a21-9b10-da97a8a97b3c","f0f7e86c-8794-4f60-91b2-ae611061df89","ae7bf8ae-4c15-44e2-9253-ec5246f86911","fcfab07d-8db2-4c1a-85fc-8ffdd92e5928","a034dc64-5238-4f6d-ac72-e171735cebcd","f5b9b0f2-a675-4189-835c-77177ec23456","1ef12c57-6844-4377-9536-1c8832d9430a","c88f8c19-50d0-4f8f-bf05-4ec81294ad24","db68935b-099f-4748-8872-86df3c0cdc54","c69dceb1-4be0-4306-a4d6-cee141b1b67c","6114ed4a-0542-455f-a7ed-1f5a61b2a057","f66b1b6b-82c7-4ecf-89c7-694d49025855","271c19a0-eccc-4801-a1e3-45ed2d1f81f9","6242246f-f711-4c70-a8a1-f1b154b12de4","16cc9239-2691-4917-b952-d47f6582819f","08aadde9-c0a6-438e-a608-b7f230bf1427","500fce2c-0b40-4874-945f-b08548d24364","38398255-8c0d-429c-bcac-98b4a88d3016"]
A2: layout | B2: {"font":"Assistant","sideMarginMm":6.35,"verticalMarginMm":19.05} | C2: {"title":[{"sheet":"שער","cell":"B4"}],"location":[{"sheet":"שער","cell":"B5"}],"client":[{"sheet":"שער","cell":"B6"}],"date":[{"sheet":"שער","cell":"B8"}],"office":[{"sheet":"שער","cell":"B12"}],"revision":[{"sheet":"שער","cell":"B14"}],"contractor":[{"sheet":"שער","cell":"D14"}],"vat":[{"sheet":"שער","cell":"F14"}],"instructions":[{"sheet":"מקרא והנחיות","cell":"A31"},{"sheet":"מקרא והנחיות","cell":"A32"},{"sheet":"מקרא והנחיות","cell":"A33"},{"sheet":"מקרא והנחיות","cell":"A34"},{"sheet":"מקרא והנחיות","cell":"A35"}]} | D2: {"width":2836,"height":771,"sha256":"11e4cb844c2fce059d04ea30f256087da08ced63e5ed936793dfe2e25a583992"}
A3: chapterId | B3: sheet | C3: active | D3: rowIds
A4: 89cf1821-72b3-4c89-91dc-dda7acdc2f13 | B4: פירוק והריסה | C4: 1 | D4: ["c0d5aee2-4c84-4ad3-9e2b-d7c0a9492955","2858f0be-e9d1-4d79-85c1-02d2fa01d511","bfb510ee-fd38-45a8-8407-63f83b2cbc9d","ea4ec611-5c31-443c-9cc8-3b29aa60fb4f","3f0127a7-21fa-4f65-a78a-3847c0f49d84","099ce812-b36f-4b53-9b46-cdf7d8c82752","a3f31d66-b815-4793-8db0-ee6176920241","bbcba1a1-129b-4ee6-bd25-69a95a000901","6183dc62-52e2-4662-a1c3-553ac0ed70a9"]
A5: cf61fba7-00ad-4d66-b23a-f20511104b42 | B5: בנייה ומחיצות פנים | C5: 1 | D5: ["e9363238-00e2-49ad-bf3f-177d43e5e746","c7a971e5-e154-4ab9-90b2-530cbf7c54a9","da3762b4-478a-409f-b339-27827d6958b9","a1a0e11e-6a7d-431e-971e-a354902b8ca0","ff54d41f-863c-44e7-9b18-e3c1cbf2cc1c","59e45f4c-c08a-40e0-bbe5-c77b8428dd71","2ebb6518-d976-4be1-8423-a37d18804655"]
A6: 0821a825-0557-4b30-bd61-a657a755cdce | B6: אינסטלציה ותברואה | C6: 1 | D6: ["a7ab8dfb-2c0a-48e6-b44b-800dc91b9939","dc9c9809-c204-4606-aef7-f1008e49e341","b2b72ee2-2fa9-44e7-aa39-bdddf082e3d1","3eab265c-1275-4a44-b790-b0871954a411","5b7b34cf-77b1-4822-9692-f6d95534cdfa","14251e6b-b7ce-46c8-9c6d-99b9832db87e","965b5eb5-98fb-4085-8d32-65a5049adb55","cef29ff1-613f-48e0-855e-eb296e7f3302","6365b3a7-ca7e-4e37-98a1-41740bf255d6"]
A7: f8e394a4-d615-44e1-9ee5-d336cee69506 | B7: חשמל והכנות תקשורת | C7: 1 | D7: ["f671a80d-911c-4daa-844e-9e29b1aeecb2","31a2e879-e495-4e9f-b2c2-008bbc51cbc8","b50b1425-a17f-4b5f-8aa1-f83a5e229ef7","10049eb0-576d-4170-98b6-e29d345d22be","381fe78a-9e9e-4ec5-907a-e3e8d2a0bdf3","bb2b4f4a-ffdd-4f27-b815-4331e3d14601","4a8f7e26-7728-4ae6-a197-237bc84c8c9a","e68ab009-c348-4fc0-a50b-5bcd4c93f05b","103626c3-c22e-447b-98fb-3dfebb9cdaeb","de8577f3-fa9c-4b4c-9cf6-05f5bdbe8c71","f0e4e920-3b04-4c22-9d93-e86d05c4d6b0"]
A8: b282e2b0-fec5-4a21-9b10-da97a8a97b3c | B8: הכנות רצפה והגבהות | C8: 1 | D8: ["d739b3bc-780a-4a72-ba86-0ab69d5555d8","279664b5-0c3b-4d71-94ff-831a0ad7f0f2"]
A9: f0f7e86c-8794-4f60-91b2-ae611061df89 | B9: איטום | C9: 1 | D9: ["0b2c232b-b1ec-4d04-9327-63c5c169d60b","e3b5eca2-2a63-4dd4-9acb-ae3c70e63581"]
A10: ae7bf8ae-4c15-44e2-9253-ec5246f86911 | B10: דלתות פנים | C10: 1 | D10: ["88b108a2-ba3a-44cb-b624-e7f2d477a59b","6af4c878-c16d-4cdc-b056-b9017d9ed215"]
A11: fcfab07d-8db2-4c1a-85fc-8ffdd92e5928 | B11: ריצוף וחיפוי אושי־אושי | C11: 1 | D11: ["035dd93f-ff8c-4c4f-82e0-fb95305e9064","e90f467b-62ad-4dc5-8390-2824cd47051d","2a77b2b0-bd89-484c-aefa-7649237266a3","529a5c22-b175-444b-a0a1-a79b20edce82","762c2a92-e28a-48bc-b6d4-aa7890919569","f33b6302-5f9a-4646-afa0-50840c5212fb","814e0b35-7c45-4f2e-9d46-c65e831796f3","11915dd1-408c-46c9-8a03-20d139f5f017"]
A12: a034dc64-5238-4f6d-ac72-e171735cebcd | B12: תקרות והנמכות | C12: 1 | D12: ["b018f255-7f74-4926-bd9d-03ca8de14c5f","90d00fb0-cde4-4ea7-96e7-6fb4866f2cbf","6931ce28-5fc3-4d9d-9a0a-6f3b1dcc9430","a6e52682-36e0-454b-96bd-ee2696af011f","bbacb34f-969a-4784-82e4-352b2d5757d0"]
A13: f5b9b0f2-a675-4189-835c-77177ec23456 | B13: צבע וגמרים דקורטיביים | C13: 1 | D13: ["65d9619e-f59f-4ffb-979d-4f212dc38e6e","57de838b-c1ff-4814-8a3e-fc2ecf82c909","5249fb67-2ebb-416a-85de-0aeb02b82fc1","7c779bf6-5dc8-491e-a313-8a6ae8be25bd","1a5045ec-62d9-4b53-bf57-e987bd4be60d"]
A14: 1ef12c57-6844-4377-9536-1c8832d9430a | B14: נגרות אושי־אושי | C14: 1 | D14: ["e6d6b168-577f-48a1-a785-79c9ce0a98c3","505199b7-23f9-46a5-bae6-2ec608970020","72e7ba87-dc88-46de-9b6c-263b6f8a03c2","c3cd28e5-5d01-4c10-8fa1-6eb41b02e3cb","dc27ed35-c9b3-444b-a671-043c55df5ff9","fb19eebb-f858-4a25-81c9-76315e81b53b","d9d2e282-ac14-48e1-977b-b51cf959cf46","7ca31fc3-ad79-4d9c-af85-8438db16427e","6f64ed20-35c0-4c0c-ae0e-6bfddc26600c","e4142fab-622c-4c97-8e40-155fc06a2ee6","c07c12c9-f785-4ac9-ba64-8c3dd32fd7a1","f6272e14-b96a-4269-8f83-fe57fa052f79","1d16f450-db46-4817-83ae-c4be601a2593","1c434242-36b3-40c9-9d75-9f3d2131bdd2"]
A15: c88f8c19-50d0-4f8f-bf05-4ec81294ad24 | B15: מסגרות אושי־אושי | C15: 1 | D15: ["ede56674-a0e0-4594-b46c-35708807b906","a91a7af2-dc99-450d-b0f0-e514181f4b96","6ac9c51a-c10d-4be4-a589-8ecbdee65bc9","e2972e79-9c46-48b0-90cc-f830e3330095","94c849cd-cf94-40cb-a323-fc827fb7177d","9c0d69cf-954b-4d90-80d9-eef1f2aa6d8a","be913337-5e8d-4009-8a1b-7543b0addea3","6d89502a-e2d8-4d8f-8c15-91e7883b0455","98ed4f35-d46a-47fc-b06a-06e1cbf28e04","a02b0c22-f069-471d-aac4-106aec900ad0","7bc1bad8-a136-40ed-a037-d1a04cc009a2"]
... A25: 38398255-8c0d-429c-bcac-98b4a88d3016 | B25: ריהוט וישיבה | C25: 1 | D25: ["88841134-2c8c-417b-8acc-6af740ad63ab","7e283deb-a816-4e49-8ff9-9746925aaea4","ac68329b-2b1b-4798-a718-ec48d7b8138e"]

Sheet פירוק והריסה
A1: 1 | B1: פירוק והריסה | G1: 89cf1821-72b3-4c89-91dc-dda7acdc2f13 | H1: chapter
A2: סעיף | B2: תיאור עבודה | C2: יח׳ | D2: כמות | E2: מחיר יחידה | F2: סה״כ | H2: columns
B3: מחירי עבודות הפירוק כוללים הגנה על הרכוש הנותר ופינוי הפסולת הנוצרת מהפירוק. פריטים המיועדים לשימוש חוזר יזוהו בפרויקט ויפורקו לשמירה. אין לחייב שוב אותו פינוי בסעיף אחר. | G3: c0d5aee2-4c84-4ad3-9e2b-d7c0a9492955 | H3: note
A4: 1.01 | B4: פירוק מחיצות פנים באזור {אזור}, כולל חיפויים, דלתות ומשקופים המיועדים לפירוק, עד גבולות העבודה המסומנים בתכנית. רכיבים לשמירה: {רכיבים}. | C4: מ"ר | F4: =IF(ISBLANK(D4),"",IF(NOT(ISNUMBER(D4)),"קלט לא תקין",IF(D4<0,"קלט לא תקין",IF(ISBLANK(E4),"",IF(OR(E4="כלול",E4="לא רלוונטי"),0,IF(NOT(ISNUMBER(E4)),"קלט לא תקין",IF(E4<0,"קלט לא תקין",ROUND(D4*E4,2)))))))) | G4: 2858f0be-e9d1-4d79-85c1-02d2fa01d511 | H4: item
A5: 1.02 | B5: פירוק תקרה או הנמכה מסוג {סוג} באזור {אזור}, לרבות התשתית המיועדת לפירוק. הטיפול בחלקים: {פינוי או שמירה להרכבה מחדש}. | C5: מ"ר | F5: =IF(ISBLANK(D5),"",IF(NOT(ISNUMBER(D5)),"קלט לא תקין",IF(D5<0,"קלט לא תקין",IF(ISBLANK(E5),"",IF(OR(E5="כלול",E5="לא רלוונטי"),0,IF(NOT(ISNUMBER(E5)),"קלט לא תקין",IF(E5<0,"קלט לא תקין",ROUND(D5*E5,2)))))))) | G5: bfb510ee-fd38-45a8-8407-63f83b2cbc9d | H5: item
A6: 1.03 | B6: פירוק ריצוף ושכבות תשתית באזור {אזור}, עד {גבול ועומק פירוק}, כהכנה לעבודות החדשות המפורטות בפרויקט. | C6: מ"ר | F6: =IF(ISBLANK(D6),"",IF(NOT(ISNUMBER(D6)),"קלט לא תקין",IF(D6<0,"קלט לא תקין",IF(ISBLANK(E6),"",IF(OR(E6="כלול",E6="לא רלוונטי"),0,IF(NOT(ISNUMBER(E6)),"קלט לא תקין",IF(E6<0,"קלט לא תקין",ROUND(D6*E6,2)))))))) | G6: ea4ec611-5c31-443c-9cc8-3b29aa60fb4f | H6: item
A7: 1.04 | B7: פירוק ופינוי ריהוט קבוע, ארונות וציוד המיועדים לפינוי באזור {אזור}; פריטים לשימוש חוזר וגבולות פירוק יפורטו לפני תחילת העבודה. | C7: קומפ' | F7: =IF(ISBLANK(D7),"",IF(NOT(ISNUMBER(D7)),"קלט לא תקין",IF(D7<0,"קלט לא תקין",IF(ISBLANK(E7),"",IF(OR(E7="כלול",E7="לא רלוונטי"),0,IF(NOT(ISNUMBER(E7)),"קלט לא תקין",IF(E7<0,"קלט לא תקין",ROUND(D7*E7,2)))))))) | G7: 3f0127a7-21fa-4f65-a78a-3847c0f49d84 | H7: item
A8: 1.05 | B8: פירוק מערכת חשמל ואביזריה באזור {אזור}, בגבולות הנקובים בתכנון. מעגלים ואביזרים שנשארים פעילים או מיועדים להרכבה מחדש: {פירוט}. | C8: קומפ' | F8: =IF(ISBLANK(D8),"",IF(NOT(ISNUMBER(D8)),"קלט לא תקין",IF(D8<0,"קלט לא תקין",IF(ISBLANK(E8),"",IF(OR(E8="כלול",E8="לא רלוונטי"),0,IF(NOT(ISNUMBER(E8)),"קלט לא תקין",IF(E8<0,"קלט לא תקין",ROUND(D8*E8,2)))))))) | G8: 099ce812-b36f-4b53-9b46-cdf7d8c82752 | H8: item
A9: 1.06 | B9: פירוק צנרת ואביזרי אינסטלציה המיועדים להחלפה באזור {אזור}, בגבולות {תחילה וסיום}; הגנת וחסימת קצוות החיבור לפי התכנון. | C9: קומפ' | F9: =IF(ISBLANK(D9),"",IF(NOT(ISNUMBER(D9)),"קלט לא תקין",IF(D9<0,"קלט לא תקין",IF(ISBLANK(E9),"",IF(OR(E9="כלול",E9="לא רלוונטי"),0,IF(NOT(ISNUMBER(E9)),"קלט לא תקין",IF(E9<0,"קלט לא תקין",ROUND(D9*E9,2)))))))) | G9: a3f31d66-b815-4793-8db0-ee6176920241 | H9: item
A10: 1.07 | B10: פירוק פתח מטיפוס {זיהוי}, לרבות {כנף, משקוף, זיגוג או תריס}, בגבולות {תכולה}; רכיבים לשימור: {פירוט}. | C10: יח' | F10: =IF(ISBLANK(D10),"",IF(NOT(ISNUMBER(D10)),"קלט לא תקין",IF(D10<0,"קלט לא תקין",IF(ISBLANK(E10),"",IF(OR(E10="כלול",E10="לא רלוונטי"),0,IF(NOT(ISNUMBER(E10)),"קלט לא תקין",IF(E10<0,"קלט לא תקין",ROUND(D10*E10,2)))))))) | G10: bbcba1a1-129b-4ee6-bd25-69a95a000901 | H10: item
A11: 1.08 | B11: פירוק שילוט קיים מטיפוס {זיהוי}, כולל רכיבי התקנה והזנה המיועדים לפירוק, ושמירה על רכיבים שסומנו להמשך שימוש. | C11: קומפ' | F11: =IF(ISBLANK(D11),"",IF(NOT(ISNUMBER(D11)),"קלט לא תקין",IF(D11<0,"קלט לא תקין",IF(ISBLANK(E11),"",IF(OR(E11="כלול",E11="לא רלוונטי"),0,IF(NOT(ISNUMBER(E11)),"קלט לא תקין",IF(E11<0,"קלט לא תקין",ROUND(D11*E11,2)))))))) | G11: 6183dc62-52e2-4662-a1c3-553ac0ed70a9 | H11: item
H12: spacer
B13: סיכום חלקי פרק 1 להעברה | F13: =SUM(F4,F5,F6,F7,F8,F9,F10,F11) -> 0 | H13: total

Sheet בנייה ומחיצות פנים
A1: 2 | B1: בנייה ומחיצות פנים | G1: cf61fba7-00ad-4d66-b23a-f20511104b42 | H1: chapter
A2: סעיף | B2: תיאור עבודה | C2: יח׳ | D2: כמות | E2: מחיר יחידה | F2: סה״כ | H2: columns
B3: מחירי המחיצות כוללים את רכיבי המערכת, התשתית, החיבורים והגמר המוגדרים בסעיף. סוגי לוחות, שכבות, בידוד ועיגון יושלמו לפי הפרויקט. גמר צבע וחיפוי מתומחרים בפרקים המיועדים להם, אלא אם הוגדר אחרת במפורש. | G3: e9363238-00e2-49ad-bf3f-177d43e5e746 | H3: note
A4: 2.01 | B4: הקמת מחיצת פנים במערכת בנייה יבשה באזור {אזור}. גובה: {גובה}; עובי ומבנה המערכת: {מפרט}; לוחות: {סוג ושכבות}; בידוד: {מפרט}; בסיס ועיגון: {פרט}. | C4: מ"ר | F4: =IF(ISBLANK(D4),"",IF(NOT(ISNUMBER(D4)),"קלט לא תקין",IF(D4<0,"קלט לא תקין",IF(ISBLANK(E4),"",IF(OR(E4="כלול",E4="לא רלוונטי"),0,IF(NOT(ISNUMBER(E4)),"קלט לא תקין",IF(E4<0,"קלט לא תקין",ROUND(D4*E4,2)))))))) | G4: c7a971e5-e154-4ab9-90b2-530cbf7c54a9 | H4: item
A5: 2.02 | B5: ביצוע עיבוי או חיפוי קיר קיים במערכת {סוג}, בגובה {גובה}, באזור {אזור}, לצורך {ייעוד}, לרבות תשתית וחיבורים כמפורט. | C5: מ"ר | F5: =IF(ISBLANK(D5),"",IF(NOT(ISNUMBER(D5)),"קלט לא תקין",IF(D5<0,"קלט לא תקין",IF(ISBLANK(E5),"",IF(OR(E5="כלול",E5="לא רלוונטי"),0,IF(NOT(ISNUMBER(E5)),"קלט לא תקין",IF(E5<0,"קלט לא תקין",ROUND(D5*E5,2)))))))) | G5: da3762b4-478a-409f-b339-27827d6958b9 | H5: item
A6: 2.03 | B6: הקמת מחיצה נמוכה כתשתית לדלפק או להפרדה באזור {אזור}, בגובה ובחתך {מידות}, במערכת {סוג}, לרבות {תכולה ועיגון}. | C6: מ.א. | F6: =IF(ISBLANK(D6),"",IF(NOT(ISNUMBER(D6)),"קלט לא תקין",IF(D6<0,"קלט לא תקין",IF(ISBLANK(E6),"",IF(OR(E6="כלול",E6="לא רלוונטי"),0,IF(NOT(ISNUMBER(E6)),"קלט לא תקין",IF(E6<0,"קלט לא תקין",ROUND(D6*E6,2)))))))) | G6: a1a0e11e-6a7d-431e-971e-a354902b8ca0 | H6: item
A7: 2.04 | B7: אספקה והתקנת מגן פינה מנירוסטה מטיפוס {טיפוס}, במידות {מידות}, עובי וגמר {מפרט}, על תשתית {סוג} ובאופן חיבור {פרט}. | C7: יח' | F7: =IF(ISBLANK(D7),"",IF(NOT(ISNUMBER(D7)),"קלט לא תקין",IF(D7<0,"קלט לא תקין",IF(ISBLANK(E7),"",IF(OR(E7="כלול",E7="לא רלוונטי"),0,IF(NOT(ISNUMBER(E7)),"קלט לא תקין",IF(E7<0,"קלט לא תקין",ROUND(D7*E7,2)))))))) | G7: ff54d41f-863c-44e7-9b18-e3c1cbf2cc1c | H7: item
A8: 2.05 | B8: אספקה והתקנת מגן קצה מנירוסטה מטיפוס {טיפוס}, במידות {מידות}, עובי וגמר {מפרט}, על תשתית {סוג} ובאופן חיבור {פרט}. | C8: יח' | F8: =IF(ISBLANK(D8),"",IF(NOT(ISNUMBER(D8)),"קלט לא תקין",IF(D8<0,"קלט לא תקין",IF(ISBLANK(E8),"",IF(OR(E8="כלול",E8="לא רלוונטי"),0,IF(NOT(ISNUMBER(E8)),"קלט לא תקין",IF(E8<0,"קלט לא תקין",ROUND(D8*E8,2)))))))) | G8: 59e45f4c-c08a-40e0-bbe5-c77b8428dd71 | H8: item
A9: 2.06 | B9: אספקה והתקנת משקוף נירוסטה לפתח {זיהוי וייעוד}, במידות {מידות}, עובי וגמר {מפרט}, לרבות החיבורים והעיגון שנקבעו לפריט. | C9: יח' | F9: =IF(ISBLANK(D9),"",IF(NOT(ISNUMBER(D9)),"קלט לא תקין",IF(D9<0,"קלט לא תקין",IF(ISBLANK(E9),"",IF(OR(E9="כלול",E9="לא רלוונטי"),0,IF(NOT(ISNUMBER(E9)),"קלט לא תקין",IF(E9<0,"קלט לא תקין",ROUND(D9*E9,2)))))))) | G9: 2ebb6518-d976-4be1-8423-a37d18804655 | H9: item
H10: spacer
B11: סיכום חלקי פרק 2 להעברה | F11: =SUM(F4,F5,F6,F7,F8,F9) -> 0 | H11: total

Sheet אינסטלציה ותברואה
A1: 3 | B1: אינסטלציה ותברואה | G1: 0821a825-0557-4b30-bd61-a657a755cdce | H1: chapter
A2: סעיף | B2: תיאור עבודה | C2: יח׳ | D2: כמות | E2: מחיר יחידה | F2: סה״כ | H2: columns
B3: מערכת המים והדלוחין תבוצע לפי תכנון הפרויקט. המחירים כוללים צנרת ואביזרי תשתית, חיבורים, הכנות ובדיקות כפי שנקבעו במפרט. אספקת כלים סניטריים וציוד אינה כלולה בסעיפי התקנה בלבד. קיום מערכת באתר אינו מעיד שאינה דורשת התאמה. | G3: a7ab8dfb-2c0a-48e6-b44b-800dc91b9939 | H3: note
A4: 3.01 | B4: ביצוע או התאמת מערכת מים ודלוחין באזור {אזור}, בין נקודות החיבור {תחילה וסיום}, לרבות {צנרת, אביזרים ומתקנים}, לפי תכנון {הפניה}. חיבור למערכת קיימת יוגדר לפי מצב האתר שנבדק. | C4: קומפ' | F4: =IF(ISBLANK(D4),"",IF(NOT(ISNUMBER(D4)),"קלט לא תקין",IF(D4<0,"קלט לא תקין",IF(ISBLANK(E4),"",IF(OR(E4="כלול",E4="לא רלוונטי"),0,IF(NOT(ISNUMBER(E4)),"קלט לא תקין",IF(E4<0,"קלט לא תקין",ROUND(D4*E4,2)))))))) | G4: dc9c9809-c204-4606-aef7-f1008e49e341 | H4: item
A5: 3.02 | B5: ביצוע נקודת מים חמים וקרים ודלוחין עבור {כיור או ציוד}, לפי תכנון הפרויקט, לרבות הצנרת ואביזרי החיבור בגבולות {תכולה}. התקנת האביזר ואספקתו: {כלולות או מוחרגות}. | C5: נק' | F5: =IF(ISBLANK(D5),"",IF(NOT(ISNUMBER(D5)),"קלט לא תקין",IF(D5<0,"קלט לא תקין",IF(ISBLANK(E5),"",IF(OR(E5="כלול",E5="לא רלוונטי"),0,IF(NOT(ISNUMBER(E5)),"קלט לא תקין",IF(E5<0,"קלט לא תקין",ROUND(D5*E5,2)))))))) | G5: b2b72ee2-2fa9-44e7-aa39-bdddf082e3d1 | H5: item
A6: 3.03 | B6: ביצוע נקודת מים קרים ודלוחין עבור {כיור או ציוד}, לפי תכנון הפרויקט, לרבות הצנרת ואביזרי החיבור בגבולות {תכולה}. | C6: נק' | F6: =IF(ISBLANK(D6),"",IF(NOT(ISNUMBER(D6)),"קלט לא תקין",IF(D6<0,"קלט לא תקין",IF(ISBLANK(E6),"",IF(OR(E6="כלול",E6="לא רלוונטי"),0,IF(NOT(ISNUMBER(E6)),"קלט לא תקין",IF(E6<0,"קלט לא תקין",ROUND(D6*E6,2)))))))) | G6: 3eab265c-1275-4a44-b790-b0871954a411 | H6: item
A7: 3.04 | B7: ביצוע נקודת דלוחין עצמאית עבור {ציוד או ייעוד}, לרבות חיבור וסיום לפי תכנון הפרויקט. אין לכלול שוב ניקוז שכבר נכלל בנקודת מים משולבת. | C7: נק' | F7: =IF(ISBLANK(D7),"",IF(NOT(ISNUMBER(D7)),"קלט לא תקין",IF(D7<0,"קלט לא תקין",IF(ISBLANK(E7),"",IF(OR(E7="כלול",E7="לא רלוונטי"),0,IF(NOT(ISNUMBER(E7)),"קלט לא תקין",IF(E7<0,"קלט לא תקין",ROUND(D7*E7,2)))))))) | G7: 5b7b34cf-77b1-4822-9692-f6d95534cdfa | H7: item
A8: 3.05 | B8: ביצוע נקודת ניקוז למיזוג אוויר מטיפוס {טיפוס}, לפי תכנון המיזוג והתברואה; קצה וגבול החיבור לקבלן המיזוג: {פירוט}. | C8: נק' | F8: =IF(ISBLANK(D8),"",IF(NOT(ISNUMBER(D8)),"קלט לא תקין",IF(D8<0,"קלט לא תקין",IF(ISBLANK(E8),"",IF(OR(E8="כלול",E8="לא רלוונטי"),0,IF(NOT(ISNUMBER(E8)),"קלט לא תקין",IF(E8<0,"קלט לא תקין",ROUND(D8*E8,2)))))))) | G8: 14251e6b-b7ce-46c8-9c6d-99b9832db87e | H8: item
A9: 3.06 | B9: התקנת תעלת ניקוז מטיפוס {טיפוס}, במידות {מידות}, על התשתית המוגדרת, וחיבורה למערכת הניקוז. אספקת התעלה, עיגון ואיטום המפגש: {חלוקת אחריות}. | C9: יח' | F9: =IF(ISBLANK(D9),"",IF(NOT(ISNUMBER(D9)),"קלט לא תקין",IF(D9<0,"קלט לא תקין",IF(ISBLANK(E9),"",IF(OR(E9="כלול",E9="לא רלוונטי"),0,IF(NOT(ISNUMBER(E9)),"קלט לא תקין",IF(E9<0,"קלט לא תקין",ROUND(D9*E9,2)))))))) | G9: 965b5eb5-98fb-4085-8d32-65a5049adb55 | H9: item
A10: 3.07 | B10: התקנת מכל הדחה סמוי וכלי סניטרי מטיפוס {טיפוס} על תשתית {בלוק או מערכת אחרת}, לרבות חיבורים ותכולת ההתקנה שנקבעה. אספקת הכלי והמכל: {אחריות}. | C10: יח' | F10: =IF(ISBLANK(D10),"",IF(NOT(ISNUMBER(D10)),"קלט לא תקין",IF(D10<0,"קלט לא תקין",IF(ISBLANK(E10),"",IF(OR(E10="כלול",E10="לא רלוונטי"),0,IF(NOT(ISNUMBER(E10)),"קלט לא תקין",IF(E10<0,"קלט לא תקין",ROUND(D10*E10,2)))))))) | G10: cef29ff1-613f-48e0-855e-eb296e7f3302 | H10: item
A11: 3.08 | B11: אספקה והתקנת מתקן חימום מים מסוג {סוג}, בקיבול או הספק {נתון}, עם אביזרים וחיבורים כמפורט בתכנון. גבולות עבודות החשמל ועיגון המתקן: {פירוט}. | C11: יח' | F11: =IF(ISBLANK(D11),"",IF(NOT(ISNUMBER(D11)),"קלט לא תקין",IF(D11<0,"קלט לא תקין",IF(ISBLANK(E11),"",IF(OR(E11="כלול",E11="לא רלוונטי"),0,IF(NOT(ISNUMBER(E11)),"קלט לא תקין",IF(E11<0,"קלט לא תקין",ROUND(D11*E11,2)))))))) | G11: 6365b3a7-ca7e-4e37-98a1-41740bf255d6 | H11: item
H12: spacer
B13: סיכום חלקי פרק 3 להעברה | F13: =SUM(F4,F5,F6,F7,F8,F9,F10,F11) -> 0 | H13: total

Sheet חשמל והכנות תקשורת
A1: 4 | B1: חשמל והכנות תקשורת | G1: f8e394a4-d615-44e1-9ee5-d336cee69506 | H1: chapter
A2: סעיף | B2: תיאור עבודה | C2: יח׳ | D2: כמות | E2: מחיר יחידה | F2: סה״כ | H2: columns
B3: עבודות החשמל כוללות תשתית, מוליכים, חיבורים ואביזרים רק בתכולה המוגדרת לכל סעיף ולפי תכנון החשמל. הכנת נקודה, התקנת גוף ואספקת גוף הן תכולות שונות. חתכי מוליכים, קטרים, הגנות, הספקים ואופן הבדיקה ייקבעו בתכנון ולא יועתקו מפרויקט קודם. | G3: f671a80d-911c-4daa-844e-9e29b1aeecb2 | H3: note
A4: 4.01 | B4: ביצוע נקודת הפעלה וחיבור למעגל תאורה מטיפוס {טיפוס}, באזור {אזור}, לפי תכנון החשמל, כולל {תשתית, חיבור ואביזרי הפעלה}. אספקת והתקנת גופי התאורה אינן נכללות בסעיף זה. | C4: נק' | F4: =IF(ISBLANK(D4),"",IF(NOT(ISNUMBER(D4)),"קלט לא תקין",IF(D4<0,"קלט לא תקין",IF(ISBLANK(E4),"",IF(OR(E4="כלול",E4="לא רלוונטי"),0,IF(NOT(ISNUMBER(E4)),"קלט לא תקין",IF(E4<0,"קלט לא תקין",ROUND(D4*E4,2)))))))) | G4: 31a2e879-e495-4e9f-b2c2-008bbc51cbc8 | H4: item
A5: 4.02 | B5: ביצוע יציאה נוספת לגוף תאורה המשויך למעגל {זיהוי}, לפי תכנון החשמל; תכולת החיבור: {פירוט}. | C5: יח' | F5: =IF(ISBLANK(D5),"",IF(NOT(ISNUMBER(D5)),"קלט לא תקין",IF(D5<0,"קלט לא תקין",IF(ISBLANK(E5),"",IF(OR(E5="כלול",E5="לא רלוונטי"),0,IF(NOT(ISNUMBER(E5)),"קלט לא תקין",IF(E5<0,"קלט לא תקין",ROUND(D5*E5,2)))))))) | G5: b50b1425-a17f-4b5f-8aa1-f83a5e229ef7 | H5: item
A6: 4.03 | B6: התקנת וחיבור גוף תאורה מטיפוס {טיפוס} על תשתית {קיימת או חדשה}, לרבות אביזרי ההתקנה המוגדרים. אספקת הגוף: {אחריות}. | C6: יח' | F6: =IF(ISBLANK(D6),"",IF(NOT(ISNUMBER(D6)),"קלט לא תקין",IF(D6<0,"קלט לא תקין",IF(ISBLANK(E6),"",IF(OR(E6="כלול",E6="לא רלוונטי"),0,IF(NOT(ISNUMBER(E6)),"קלט לא תקין",IF(E6<0,"קלט לא תקין",ROUND(D6*E6,2)))))))) | G6: 10049eb0-576d-4170-98b6-e29d345d22be | H6: item
A7: 4.04 | B7: ביצוע נקודת כוח חד־פאזית עבור {ייעוד}, באזור {אזור}, עם האביזר והתשתית לפי תכנון החשמל ובגבולות {תכולה}. | C7: נק' | F7: =IF(ISBLANK(D7),"",IF(NOT(ISNUMBER(D7)),"קלט לא תקין",IF(D7<0,"קלט לא תקין",IF(ISBLANK(E7),"",IF(OR(E7="כלול",E7="לא רלוונטי"),0,IF(NOT(ISNUMBER(E7)),"קלט לא תקין",IF(E7<0,"קלט לא תקין",ROUND(D7*E7,2)))))))) | G7: 381fe78a-9e9e-4ec5-907a-e3e8d2a0bdf3 | H7: item
A8: 4.05 | B8: ביצוע נקודת כוח תלת־פאזית עבור {ציוד}, לפי מפרט ההזנה של מתכנן החשמל ויצרן הציוד. אביזר החיבור וגבול העבודה: {פירוט}. | C8: נק' | F8: =IF(ISBLANK(D8),"",IF(NOT(ISNUMBER(D8)),"קלט לא תקין",IF(D8<0,"קלט לא תקין",IF(ISBLANK(E8),"",IF(OR(E8="כלול",E8="לא רלוונטי"),0,IF(NOT(ISNUMBER(E8)),"קלט לא תקין",IF(E8<0,"קלט לא תקין",ROUND(D8*E8,2)))))))) | G8: bb2b4f4a-ffdd-4f27-b815-4331e3d14601 | H8: item
A9: 4.06 | B9: ביצוע נקודת הזנה למיזוג אוויר עבור {יחידה}, בהתאם לתכנון החשמל והמיזוג, לרבות אביזר סיום וגבול חיבור {פירוט}. | C9: נק' | F9: =IF(ISBLANK(D9),"",IF(NOT(ISNUMBER(D9)),"קלט לא תקין",IF(D9<0,"קלט לא תקין",IF(ISBLANK(E9),"",IF(OR(E9="כלול",E9="לא רלוונטי"),0,IF(NOT(ISNUMBER(E9)),"קלט לא תקין",IF(E9<0,"קלט לא תקין",ROUND(D9*E9,2)))))))) | G9: 4a8f7e26-7728-4ae6-a197-237bc84c8c9a | H9: item
A10: 4.07 | B10: ביצוע נקודת הזנה למפוח עבור {יחידה וייעוד}, בהתאם לתכנון החשמל והאוורור, לרבות אביזר סיום וגבול חיבור {פירוט}. | C10: נק' | F10: =IF(ISBLANK(D10),"",IF(NOT(ISNUMBER(D10)),"קלט לא תקין",IF(D10<0,"קלט לא תקין",IF(ISBLANK(E10),"",IF(OR(E10="כלול",E10="לא רלוונטי"),0,IF(NOT(ISNUMBER(E10)),"קלט לא תקין",IF(E10<0,"קלט לא תקין",ROUND(D10*E10,2)))))))) | G10: e68ab009-c348-4fc0-a50b-5bcd4c93f05b | H10: item
A11: 4.08 | B11: ביצוע תשתית תקשורת מטיפוס {סוג}, בין נקודות {קצוות}, לרבות צנרת, חוט משיכה ואביזרי סיום שנקבעו. כבילה פעילה וציוד קצה: {תכולה ואחריות}. | C11: נק' | F11: =IF(ISBLANK(D11),"",IF(NOT(ISNUMBER(D11)),"קלט לא תקין",IF(D11<0,"קלט לא תקין",IF(ISBLANK(E11),"",IF(OR(E11="כלול",E11="לא רלוונטי"),0,IF(NOT(ISNUMBER(E11)),"קלט לא תקין",IF(E11<0,"קלט לא תקין",ROUND(D11*E11,2)))))))) | G11: 103626c3-c22e-447b-98fb-3dfebb9cdaeb | H11: item
A12: 4.09 | B12: אספקה והתקנת לוח חשמל {זיהוי}, כולל מכלול הרכיבים, הסימון, החיווט והחיבור שנקבעו בתכנון החשמל. גודל החיבור והמפרט יושלמו בפרויקט. | C12: קומפ' | F12: =IF(ISBLANK(D12),"",IF(NOT(ISNUMBER(D12)),"קלט לא תקין",IF(D12<0,"קלט לא תקין",IF(ISBLANK(E12),"",IF(OR(E12="כלול",E12="לא רלוונטי"),0,IF(NOT(ISNUMBER(E12)),"קלט לא תקין",IF(E12<0,"קלט לא תקין",ROUND(D12*E12,2)))))))) | G12: de8577f3-fa9c-4b4c-9cf6-05f5bdbe8c71 | H12: item
A13: 4.10 | B13: ביצוע מערכת תאורת חירום בתכולת {היקף}, לפי תכנון החשמל והבטיחות המאושרים לפרויקט; אספקה, התקנה וחיבורים: {פירוט}. | C13: קומפ' | F13: =IF(ISBLANK(D13),"",IF(NOT(ISNUMBER(D13)),"קלט לא תקין",IF(D13<0,"קלט לא תקין",IF(ISBLANK(E13),"",IF(OR(E13="כלול",E13="לא רלוונטי"),0,IF(NOT(ISNUMBER(E13)),"קלט לא תקין",IF(E13<0,"קלט לא תקין",ROUND(D13*E13,2)))))))) | G13: f0e4e920-3b04-4c22-9d93-e86d05c4d6b0 | H13: item
H14: spacer
B15: סיכום חלקי פרק 4 להעברה | F15: =SUM(F4,F5,F6,F7,F8,F9,F10,F11,F12,F13) -> 0 | H15: total

Sheet הכנות רצפה והגבהות
A1: 5 | B1: הכנות רצפה והגבהות | G1: b282e2b0-fec5-4a21-9b10-da97a8a97b3c | H1: chapter
A2: סעיף | B2: תיאור עבודה | C2: יח׳ | D2: כמות | E2: מחיר יחידה | F2: סה״כ | H2: columns
B3: הכנת רצפה והגבהה יפורטו רק כשנדרשות בפרויקט. יש להגדיר גבול בין הכנת המשטח, איטום וריצוף, בלי לחייב אותה שכבה פעמיים. חומר, עומס ומפלסים ייקבעו בתכנון המאושר. | G3: d739b3bc-780a-4a72-ba86-0ab69d5555d8 | H3: note
A4: 5.01 | B4: ביצוע שכבת הכנה, מילוי או הגבהה באזור {אזור}, מחומר {מערכת}, בעובי ובמפלס {נתונים}, לרבות {תשתית, גמר והשלמות נכללים}, לפי פרט מאושר. | C4: מ"ר | F4: =IF(ISBLANK(D4),"",IF(NOT(ISNUMBER(D4)),"קלט לא תקין",IF(D4<0,"קלט לא תקין",IF(ISBLANK(E4),"",IF(OR(E4="כלול",E4="לא רלוונטי"),0,IF(NOT(ISNUMBER(E4)),"קלט לא תקין",IF(E4<0,"קלט לא תקין",ROUND(D4*E4,2)))))))) | G4: 279664b5-0c3b-4d71-94ff-831a0ad7f0f2 | H4: item
H5: spacer
H6: spacer
B7: סיכום חלקי פרק 5 להעברה | F7: =SUM(F4) -> 0 | H7: total

Sheet איטום
A1: 6 | B1: איטום | G1: f0f7e86c-8794-4f60-91b2-ae611061df89 | H1: chapter
A2: סעיף | B2: תיאור עבודה | C2: יח׳ | D2: כמות | E2: מחיר יחידה | F2: סה״כ | H2: columns
B3: מערכת האיטום תיקבע לפי התשתית, השימוש, החדירות והמפגשים בפרויקט. כל סעיף יפרט את הכנת התשתית, סיומות, טיפול בנקזים ובפתחים ובדיקות נדרשות. אין ברירת מחדל לשיטת איטום, עובי, גובה רולקה או מותג. | G3: 0b2c232b-b1ec-4d04-9327-63c5c169d60b | H3: note
A4: 6.01 | B4: ביצוע איטום באזור רטוב {זיהוי ואזור}, במערכת {מפרט מאושר}, לרבות הכנת תשתית, מפגשי קיר ורצפה, חדירות וסיומות לפי הפרט. בדיקות ותכולת ההכנה: {פירוט}. | C4: מ"ר | F4: =IF(ISBLANK(D4),"",IF(NOT(ISNUMBER(D4)),"קלט לא תקין",IF(D4<0,"קלט לא תקין",IF(ISBLANK(E4),"",IF(OR(E4="כלול",E4="לא רלוונטי"),0,IF(NOT(ISNUMBER(E4)),"קלט לא תקין",IF(E4<0,"קלט לא תקין",ROUND(D4*E4,2)))))))) | G4: e3b5eca2-2a63-4dd4-9acb-ae3c70e63581 | H4: item
H5: spacer
H6: spacer
B7: סיכום חלקי פרק 6 להעברה | F7: =SUM(F4) -> 0 | H7: total

Sheet דלתות פנים
A1: 7 | B1: דלתות פנים | G1: ae7bf8ae-4c15-44e2-9253-ec5246f86911 | H1: chapter
A2: סעיף | B2: תיאור עבודה | C2: יח׳ | D2: כמות | E2: מחיר יחידה | F2: סה״כ | H2: columns
B3: מחיר כל טיפוס דלת כולל כנף, משקוף, הלבשות, פרזול, גמר, הובלה והרכבה לפי תיאור הסעיף. סוגי מילוי, צירים, פתיחה והתאמת נגישות או בטיחות יוגדרו בפרויקט; אין הוראה כללית של פרזול הסותרת טיפוס דלת. | G3: 88b108a2-ba3a-44cb-b624-e7f2d477a59b | H3: note
A4: 7.01 | B4: אספקה והתקנת דלת פנים מטיפוס {זיהוי}. מידות ופתיחה: {מידות וכיוון}; כנף ומילוי: {מפרט}; משקוף והלבשות: {מפרט}; פרזול: {מפרט}; גמר וגוון: {מפרט}; תכנית ופרט: {הפניה}. | C4: יח' | F4: =IF(ISBLANK(D4),"",IF(NOT(ISNUMBER(D4)),"קלט לא תקין",IF(D4<0,"קלט לא תקין",IF(ISBLANK(E4),"",IF(OR(E4="כלול",E4="לא רלוונטי"),0,IF(NOT(ISNUMBER(E4)),"קלט לא תקין",IF(E4<0,"קלט לא תקין",ROUND(D4*E4,2)))))))) | G4: 6af4c878-c16d-4cdc-b056-b9017d9ed215 | H4: item
H5: spacer
H6: spacer
B7: סיכום חלקי פרק 7 להעברה | F7: =SUM(F4) -> 0 | H7: total

Sheet ריצוף וחיפוי אושי־אושי
A1: 8 | B1: ריצוף וחיפוי אושי־אושי | G1: fcfab07d-8db2-4c1a-85fc-8ffdd92e5928 | H1: chapter
A2: סעיף | B2: תיאור עבודה | C2: יח׳ | D2: כמות | E2: מחיר יחידה | F2: סה״כ | H2: columns
B3: מחירי עבודות הריצוף והחיפוי כוללים הכנת תשתית בתכולה שנקבעה, חומרי עזר, חיתוכים, התאמות, פינות ורובה בהתאם למפרט. אספקת האריחים תתומחר בפרק האספקות כשאינו כבוי; פנלים המופיעים בסעיף נפרד אינם כלולים שוב במחיר השטח. | G3: 035dd93f-ff8c-4c4f-82e0-fb95305e9064 | H3: note
A4: 8.01 | B4: ריצוף חלל ציבורי ואזור ישיבה {אזור}, באריחי גרניט פורצלן שחור משופשף במידות 120×60 ס״מ, עם מישקים 2 מ״מ ורובה שחורה, על תשתית {סוג לפי הסניף}. אספקת האריחים {אחריות}; גמר מפגשים וסיומות לפי פרט {הפניה}. | C4: מ"ר | F4: =IF(ISBLANK(D4),"",IF(NOT(ISNUMBER(D4)),"קלט לא תקין",IF(D4<0,"קלט לא תקין",IF(ISBLANK(E4),"",IF(OR(E4="כלול",E4="לא רלוונטי"),0,IF(NOT(ISNUMBER(E4)),"קלט לא תקין",IF(E4<0,"קלט לא תקין",ROUND(D4*E4,2)))))))) | G4: e90f467b-62ad-4dc5-8390-2824cd47051d | H4: item
A5: 8.02 | B5: ריצוף שטח מטבח או דלפק הכנת מזון {אזור}, באריחי גרניט פורצלן אנטיסליפ במידות 30×30 ס״מ, עם מישקים 3 מ״מ ורובה שחורה. סוג הרובה ודרגת ההחלקה {אישור לפרויקט לפי OS-07}; טיפול במפגשים ובנקזים לפי פרט {הפניה}. | C5: מ"ר | F5: =IF(ISBLANK(D5),"",IF(NOT(ISNUMBER(D5)),"קלט לא תקין",IF(D5<0,"קלט לא תקין",IF(ISBLANK(E5),"",IF(OR(E5="כלול",E5="לא רלוונטי"),0,IF(NOT(ISNUMBER(E5)),"קלט לא תקין",IF(E5<0,"קלט לא תקין",ROUND(D5*E5,2)))))))) | G5: 2a77b2b0-bd89-484c-aefa-7649237266a3 | H5: item
A6: 8.03 | B6: חיפוי קירות ועמודים באזור {אזור}, באריחי גרניט פורצלן בגוון בטון משופשף במידות 120×60 ס״מ, לגובה {גובה}, עם מישקים 6 מ״מ ורובה טמבור אפור כהה 120. גמר פינות בגרונג. תשתית ואחריות אספקת האריחים {פירוט}; אין להחיל מידת אריח זו אוטומטית על דופן דלפק חתוכה. | C6: מ"ר | F6: =IF(ISBLANK(D6),"",IF(NOT(ISNUMBER(D6)),"קלט לא תקין",IF(D6<0,"קלט לא תקין",IF(ISBLANK(E6),"",IF(OR(E6="כלול",E6="לא רלוונטי"),0,IF(NOT(ISNUMBER(E6)),"קלט לא תקין",IF(E6<0,"קלט לא תקין",ROUND(D6*E6,2)))))))) | G6: 529a5c22-b175-444b-a0a1-a79b20edce82 | H6: item
A7: 8.04 | B7: חיפוי דופן חיצונית קדמית של דלפק {זיהוי}, באריחי קרמיקה דקורטיבית משולבת פסי פליז, ללא פוגות, על תשתית {סוג}. מידות האריחים {מידות לפי הפרט}; במקורות מצוין 100×10 ס״מ עם אפשרות לשינוי, ולכן אינה מידה קבועה. פרופילי שלד וחיבוריהם מתומחרים בפרק המסגרות. | C7: מ"ר | F7: =IF(ISBLANK(D7),"",IF(NOT(ISNUMBER(D7)),"קלט לא תקין",IF(D7<0,"קלט לא תקין",IF(ISBLANK(E7),"",IF(OR(E7="כלול",E7="לא רלוונטי"),0,IF(NOT(ISNUMBER(E7)),"קלט לא תקין",IF(E7<0,"קלט לא תקין",ROUND(D7*E7,2)))))))) | G7: 762c2a92-e28a-48bc-b6d4-aa7890919569 | H7: item
A8: 8.05 | B8: חיפוי דופן פנימית לדלפק {זיהוי}, באריחי קרמיקה שחורה, לגובה {גובה}, עם מישקים 2 מ״מ ורובה שחורה. מידות האריחים {בחירה לפרויקט לפי OS-03}; תשתית וגמר מפגשים {פרט}. אין לחייב שוב חיפוי פורמייקה באותו שטח. | C8: מ"ר | F8: =IF(ISBLANK(D8),"",IF(NOT(ISNUMBER(D8)),"קלט לא תקין",IF(D8<0,"קלט לא תקין",IF(ISBLANK(E8),"",IF(OR(E8="כלול",E8="לא רלוונטי"),0,IF(NOT(ISNUMBER(E8)),"קלט לא תקין",IF(E8<0,"קלט לא תקין",ROUND(D8*E8,2)))))))) | G8: f33b6302-5f9a-4646-afa0-50840c5212fb | H8: item
A9: 8.06 | B9: התקנת פנל תואם לריצוף {חומר וגמר}, בגובה {גובה}, לאורך האזור {אזור}, לרבות פינות וסיומות לפי הפרט. | C9: מ.א. | F9: =IF(ISBLANK(D9),"",IF(NOT(ISNUMBER(D9)),"קלט לא תקין",IF(D9<0,"קלט לא תקין",IF(ISBLANK(E9),"",IF(OR(E9="כלול",E9="לא רלוונטי"),0,IF(NOT(ISNUMBER(E9)),"קלט לא תקין",IF(E9<0,"קלט לא תקין",ROUND(D9*E9,2)))))))) | G9: 814e0b35-7c45-4f2e-9d46-c65e831796f3 | H9: item
H10: spacer
A11: 8 | B11: ריצוף וחיפוי אושי־אושי (המשך) | H11: heading
A12: סעיף | B12: תיאור עבודה | C12: יח׳ | D12: כמות | E12: מחיר יחידה | F12: סה״כ | H12: columns
A13: 8.07 | B13: חיפוי קיר באזור {אזור}, באריחי גרניט פורצלן בגוון חלודה משופשף במידות 120×60 ס״מ, לגובה {גובה}, בשילוב פרופילים שקועים בגוון פליז ברוחב 2 ס״מ בפוגות, ורובה טמבור חום 105 בפוגות האנכיות; פינות בגרונג. תשתית ואחריות אספקת אריחים ופרופילים {פירוט}. אם הפרופילים מתומחרים בנפרד יש להחריגם כאן במפורש. | C13: מ"ר | F13: =IF(ISBLANK(D13),"",IF(NOT(ISNUMBER(D13)),"קלט לא תקין",IF(D13<0,"קלט לא תקין",IF(ISBLANK(E13),"",IF(OR(E13="כלול",E13="לא רלוונטי"),0,IF(NOT(ISNUMBER(E13)),"קלט לא תקין",IF(E13<0,"קלט לא תקין",ROUND(D13*E13,2)))))))) | G13: 11915dd1-408c-46c9-8a03-20d139f5f017 | H13: item
H14: spacer
H15: spacer
B16: סיכום חלקי פרק 8 להעברה | F16: =SUM(F4,F5,F6,F7,F8,F9,F13) -> 0 | H16: total

Sheet תקרות והנמכות
A1: 9 | B1: תקרות והנמכות | G1: a034dc64-5238-4f6d-ac72-e171735cebcd | H1: chapter
A2: סעיף | B2: תיאור עבודה | C2: יח׳ | D2: כמות | E2: מחיר יחידה | F2: סה״כ | H2: columns
B3: המחירים כוללים תשתית, תלייה, חיבורים, פרופילי גמר ופתחים למערכות לפי מפרט התקרה. יש להגדיר סוג לוח או אריח, גובה, טיפול אקוסטי וחיזוקים. גמר צבע מתומחר בנפרד אם אינו מפורש כחלק מהמוצר. | G3: b018f255-7f74-4926-bd9d-03ca8de14c5f | H3: note
A4: 9.01 | B4: ביצוע הנמכת תקרה באזור {אזור}, במערכת {סוג ושכבות}, בגובה {גובה}, לרבות התשתית, פתחים וחיזוקים המפורטים בתכנון. | C4: מ"ר | F4: =IF(ISBLANK(D4),"",IF(NOT(ISNUMBER(D4)),"קלט לא תקין",IF(D4<0,"קלט לא תקין",IF(ISBLANK(E4),"",IF(OR(E4="כלול",E4="לא רלוונטי"),0,IF(NOT(ISNUMBER(E4)),"קלט לא תקין",IF(E4<0,"קלט לא תקין",ROUND(D4*E4,2)))))))) | G4: 90d00fb0-cde4-4ea7-96e7-6fb4866f2cbf | H4: item
A5: 9.02 | B5: ביצוע קרניז מטיפוס {טיפוס}, בחתך ובגובה {מידות}, באזור {אזור}, לרבות הכנה לתאורה או למיזוג לפי הפרט וללא אספקת גוף התאורה. | C5: מ.א. | F5: =IF(ISBLANK(D5),"",IF(NOT(ISNUMBER(D5)),"קלט לא תקין",IF(D5<0,"קלט לא תקין",IF(ISBLANK(E5),"",IF(OR(E5="כלול",E5="לא רלוונטי"),0,IF(NOT(ISNUMBER(E5)),"קלט לא תקין",IF(E5<0,"קלט לא תקין",ROUND(D5*E5,2)))))))) | G5: 6931ce28-5fc3-4d9d-9a0a-6f3b1dcc9430 | H5: item
A6: 9.03 | B6: אספקה והתקנת תקרת מגשי פח ברוחב 30 ס״מ, בגמר לבן RAL 9010, עם פרופיל סיום L, באזור מטבח או מחסן {אזור}, לרבות תשתית, תלייה ופתחים לפי התכנון. גובה ועובי הפח {מפרט הסניף}. | C6: מ"ר | F6: =IF(ISBLANK(D6),"",IF(NOT(ISNUMBER(D6)),"קלט לא תקין",IF(D6<0,"קלט לא תקין",IF(ISBLANK(E6),"",IF(OR(E6="כלול",E6="לא רלוונטי"),0,IF(NOT(ISNUMBER(E6)),"קלט לא תקין",IF(E6<0,"קלט לא תקין",ROUND(D6*E6,2)))))))) | G6: a6e52682-36e0-454b-96bd-ee2696af011f | H6: item
A7: 9.04 | B7: אספקה והתקנת תקרה אקוסטית מסוג {סוג}, במודול ובגמר {מפרט}, באזור {אזור}, לרבות התשתית והחיבורים המתאימים כמפורט בתכנון. | C7: מ"ר | F7: =IF(ISBLANK(D7),"",IF(NOT(ISNUMBER(D7)),"קלט לא תקין",IF(D7<0,"קלט לא תקין",IF(ISBLANK(E7),"",IF(OR(E7="כלול",E7="לא רלוונטי"),0,IF(NOT(ISNUMBER(E7)),"קלט לא תקין",IF(E7<0,"קלט לא תקין",ROUND(D7*E7,2)))))))) | G7: bbacb34f-969a-4784-82e4-352b2d5757d0 | H7: item
H8: spacer
B9: סיכום חלקי פרק 9 להעברה | F9: =SUM(F4,F5,F6,F7) -> 0 | H9: total

Sheet צבע וגמרים דקורטיביים
A1: 10 | B1: צבע וגמרים דקורטיביים | G1: f5b9b0f2-a675-4189-835c-77177ec23456 | H1: chapter
A2: סעיף | B2: תיאור עבודה | C2: יח׳ | D2: כמות | E2: מחיר יחידה | F2: סה״כ | H2: columns
B3: עבודות הצבע כוללות תיקונים, החלקה וחומרי יסוד לפי המשטח והוראות המוצר. שלושה גמרי קיר מתומחרים בנפרד: נישה באפור טמבור 1537T; קירות מחסן בלבן; טיח אפקט בטון משופשף טמבור 440 לקירות או עמודים שסומנו כך בתכנון. תקרות גבס וקרניזים שחורים לפי הסעיף הנפרד. אין להחיל גוון אחד על כל המשטחים ואין להעתיק הוראות דילול ישנות. | G3: 65d9619e-f59f-4ffb-979d-4f212dc38e6e | H3: note
A4: 10.01 | B4: הכנת וצביעת נישה או קטע קיר מסומן באזור {אזור}, לרבות תיקוני תשתית והחלקה, בצבע אקרילי מסוג סופרקריל בשתי שכבות לפחות ועד כיסוי מלא, בגוון אפור טמבור 1537T. חומר יסוד לפי המשטח והוראות המוצר. | C4: מ"ר | F4: =IF(ISBLANK(D4),"",IF(NOT(ISNUMBER(D4)),"קלט לא תקין",IF(D4<0,"קלט לא תקין",IF(ISBLANK(E4),"",IF(OR(E4="כלול",E4="לא רלוונטי"),0,IF(NOT(ISNUMBER(E4)),"קלט לא תקין",IF(E4<0,"קלט לא תקין",ROUND(D4*E4,2)))))))) | G4: 57de838b-c1ff-4814-8a3e-fc2ecf82c909 | H4: item
A5: 10.02 | B5: הכנת וצביעת תקרות גבס והנמכות באזור {אזור}, לרבות תיקוני תשתית ושפכטל אמריקאי עד החלקה, בצבע אקרילי מסוג סופרקריל בשתי שכבות לפחות ועד כיסוי מלא, בגוון שחור. קוד גוון וברק {אישור לפי OS-04}; חומר יסוד לפי המשטח והוראות המוצר. אין לכלול כאן גמר מפעלי של תקרת המגשים. | C5: מ"ר | F5: =IF(ISBLANK(D5),"",IF(NOT(ISNUMBER(D5)),"קלט לא תקין",IF(D5<0,"קלט לא תקין",IF(ISBLANK(E5),"",IF(OR(E5="כלול",E5="לא רלוונטי"),0,IF(NOT(ISNUMBER(E5)),"קלט לא תקין",IF(E5<0,"קלט לא תקין",ROUND(D5*E5,2)))))))) | G5: 5249fb67-2ebb-416a-85de-0aeb02b82fc1 | H5: item
A6: 10.03 | B6: ביצוע טיח דקורטיבי אפקט בטון משופשף של טמבור, בגוון 440, על קירות או עמודים מסומנים באזור {אזור}, בשתי שכבות לפחות ועד כיסוי מלא, לרבות הכנת תשתית ושפכטל עד החלקה לפי המשטח והוראות המוצר. | C6: מ"ר | F6: =IF(ISBLANK(D6),"",IF(NOT(ISNUMBER(D6)),"קלט לא תקין",IF(D6<0,"קלט לא תקין",IF(ISBLANK(E6),"",IF(OR(E6="כלול",E6="לא רלוונטי"),0,IF(NOT(ISNUMBER(E6)),"קלט לא תקין",IF(E6<0,"קלט לא תקין",ROUND(D6*E6,2)))))))) | G6: 7c779bf6-5dc8-491e-a313-8a6ae8be25bd | H6: item
A7: 10.04 | B7: הכנת וצביעת קירות מחסן {זיהוי}, לרבות תיקוני תשתית והכנת משטח, בצבע אקרילי מסוג סופרקריל בשתי שכבות לפחות ועד כיסוי מלא, בגוון לבן. חומר יסוד לפי המשטח והוראות המוצר. | C7: מ"ר | F7: =IF(ISBLANK(D7),"",IF(NOT(ISNUMBER(D7)),"קלט לא תקין",IF(D7<0,"קלט לא תקין",IF(ISBLANK(E7),"",IF(OR(E7="כלול",E7="לא רלוונטי"),0,IF(NOT(ISNUMBER(E7)),"קלט לא תקין",IF(E7<0,"קלט לא תקין",ROUND(D7*E7,2)))))))) | G7: 1a5045ec-62d9-4b53-bf57-e987bd4be60d | H7: item
H8: spacer
B9: סיכום חלקי פרק 10 להעברה | F9: =SUM(F4,F5,F6,F7) -> 0 | H9: total

Sheet נגרות אושי־אושי
A1: 11 | B1: נגרות אושי־אושי | G1: 1ef12c57-6844-4377-9536-1c8832d9430a | H1: chapter
A2: סעיף | B2: תיאור עבודה | C2: יח׳ | D2: כמות | E2: מחיר יחידה | F2: סה״כ | H2: columns
B3: מחיר כל פריט נגרות כולל חומרים, פרזול, גמר, הובלה והרכבה שפורטו. מפרט רכיבי אלון: לוחות עץ לבוד מצופים פורניר אלון שטרייף ועץ מסיבי אלון; גמר לכה מט משי 15% ברק. ברכיבי פורמייקה: פורמקס 3199. גוון הבייץ 1067 GV; אין להחליף את האלון או דגם הפורמייקה בשדה חומר כללי. מתכת, משטחים מיוחדים, זיגוג וציוד בסעיפים נפרדים מוחרגים. | G3: e6d6b168-577f-48a1-a785-79c9ce0a98c3 | H3: note
A4: 11.01 | B4: אספקה והתקנת משטח הגשה ואכילה לדלפק {זיהוי}, מעץ מסיבי אלון בעובי 2 ס״מ, עם קנט קדמי 8 ס״מ וקנט אחורי 4 ס״מ, בגמר לכה מט משי 15% ברק. בייץ 1067 GV; אורך, רוחב, צורה וגובה התקנה {מידות סניף}. שלד, דפנות ומשטחים מיוחדים בסעיפים נפרדים אינם כלולים. | C4: מ.א. | F4: =IF(ISBLANK(D4),"",IF(NOT(ISNUMBER(D4)),"קלט לא תקין",IF(D4<0,"קלט לא תקין",IF(ISBLANK(E4),"",IF(OR(E4="כלול",E4="לא רלוונטי"),0,IF(NOT(ISNUMBER(E4)),"קלט לא תקין",IF(E4<0,"קלט לא תקין",ROUND(D4*E4,2)))))))) | G4: 505199b7-23f9-46a5-bae6-2ec608970020 | H4: item
A5: 11.02 | B5: אספקה והתקנת דופן פנימית לדלפק {זיהוי}, בגובה ובעובי {מידות}, על תשתית {סוג}, לרבות פתחים והתאמות לציוד. גמר נבחר {חיפוי קרמי לפי פרק ריצוף או פורמייקה פורמקס 3199 לפי פרט הסניף}; יש להשאיר בחירה אחת. בחיפוי קרמי הנגרות כוללת תשתית בלבד והחיפוי מתומחר בנפרד. | C5: מ.א. | F5: =IF(ISBLANK(D5),"",IF(NOT(ISNUMBER(D5)),"קלט לא תקין",IF(D5<0,"קלט לא תקין",IF(ISBLANK(E5),"",IF(OR(E5="כלול",E5="לא רלוונטי"),0,IF(NOT(ISNUMBER(E5)),"קלט לא תקין",IF(E5<0,"קלט לא תקין",ROUND(D5*E5,2)))))))) | G5: 72e7ba87-dc88-46de-9b6c-263b6f8a03c2 | H5: item
A6: 11.03 | B6: אספקה והתקנת חיפוי נגרות גלוי לדלפק {זיהוי}, רק בשטח המסומן לנגרות בפרט, מלוחות עץ לבוד מצופים פורניר אלון שטרייף ועץ מסיבי אלון לפי המפרט המשותף, בגמר לכה מט משי 15% ברק ובייץ 1067 GV. גובה וחלוקה {מידות}; בשטח המיועד לקרמיקה יש לתמחר תשתית בלבד בסעיף התשתית, ללא חיפוי אלון נוסף. | C6: מ.א. | F6: =IF(ISBLANK(D6),"",IF(NOT(ISNUMBER(D6)),"קלט לא תקין",IF(D6<0,"קלט לא תקין",IF(ISBLANK(E6),"",IF(OR(E6="כלול",E6="לא רלוונטי"),0,IF(NOT(ISNUMBER(E6)),"קלט לא תקין",IF(E6<0,"קלט לא תקין",ROUND(D6*E6,2)))))))) | G6: c3cd28e5-5d01-4c10-8fa1-6eb41b02e3cb | H6: item
A7: 11.04 | B7: אספקה והתקנת שער או דלת כניסה לדלפק מטיפוס {טיפוס}, במידות {מידות}, מחומר ובגמר {מפרט}, לרבות מסגרת, צירים, סגירה וחיבורים כפי שנקבעו בפרט. | C7: יח' | F7: =IF(ISBLANK(D7),"",IF(NOT(ISNUMBER(D7)),"קלט לא תקין",IF(D7<0,"קלט לא תקין",IF(ISBLANK(E7),"",IF(OR(E7="כלול",E7="לא רלוונטי"),0,IF(NOT(ISNUMBER(E7)),"קלט לא תקין",IF(E7<0,"קלט לא תקין",ROUND(D7*E7,2)))))))) | G7: dc27ed35-c9b3-444b-a671-043c55df5ff9 | H7: item
A8: 11.05 | B8: התקנת לוחות תשתית לדופן דלפק {זיהוי}, מחומר ובעובי {מפרט}, על גבי {תשתית}, כהכנה לחיפוי {חומר}. החיפוי הסופי מתומחר בפרק הריצוף והחיפוי או בפרק המשטחים. | C8: מ"ר | F8: =IF(ISBLANK(D8),"",IF(NOT(ISNUMBER(D8)),"קלט לא תקין",IF(D8<0,"קלט לא תקין",IF(ISBLANK(E8),"",IF(OR(E8="כלול",E8="לא רלוונטי"),0,IF(NOT(ISNUMBER(E8)),"קלט לא תקין",IF(E8<0,"קלט לא תקין",ROUND(D8*E8,2)))))))) | G8: fb19eebb-f858-4a25-81c9-76315e81b53b | H8: item
A9: 11.06 | B9: אספקה והתקנת יחידת מדפים או בר תצוגה אחורי {זיהוי}, מלוחות עץ לבוד בגמר פורניר אלון שטרייף, עם קנטים קדמיים מעץ מסיבי אלון, בגמר לכה מט משי 15% ברק ובייץ 1067 GV. מידות, חלוקה וחתך קנט {מפרט סניף}. מסגרות התמיכה והמראות מתומחרות בנפרד. | C9: מ"ר | F9: =IF(ISBLANK(D9),"",IF(NOT(ISNUMBER(D9)),"קלט לא תקין",IF(D9<0,"קלט לא תקין",IF(ISBLANK(E9),"",IF(OR(E9="כלול",E9="לא רלוונטי"),0,IF(NOT(ISNUMBER(E9)),"קלט לא תקין",IF(E9<0,"קלט לא תקין",ROUND(D9*E9,2)))))))) | G9: d9d2e282-ac14-48e1-977b-b51cf959cf46 | H9: item
H10: spacer
A11: 11 | B11: נגרות אושי־אושי (המשך) | H11: heading
A12: סעיף | B12: תיאור עבודה | C12: יח׳ | D12: כמות | E12: מחיר יחידה | F12: סה״כ | H12: columns
A13: 11.07 | B13: אספקה והתקנת עמדת מלצרים מטיפוס {טיפוס}, במידות {מידות}, הכוללת ארון, חלוקה פנימית, דלתות ומגירות {פירוט}; חומרי פנים וחוץ, גמר ופרזול {מפרט}. | C13: יח' | F13: =IF(ISBLANK(D13),"",IF(NOT(ISNUMBER(D13)),"קלט לא תקין",IF(D13<0,"קלט לא תקין",IF(ISBLANK(E13),"",IF(OR(E13="כלול",E13="לא רלוונטי"),0,IF(NOT(ISNUMBER(E13)),"קלט לא תקין",IF(E13<0,"קלט לא תקין",ROUND(D13*E13,2)))))))) | G13: 7ca31fc3-ad79-4d9c-af85-8438db16427e | H13: item
A14: 11.08 | B14: אספקה והתקנת עמדת משלוחים מטיפוס {טיפוס}, במידות {מידות}, מחומרים ובגמר {מפרט}, לרבות חלוקה פנימית, פרזול ופתחים המוגדרים לפריט. | C14: יח' | F14: =IF(ISBLANK(D14),"",IF(NOT(ISNUMBER(D14)),"קלט לא תקין",IF(D14<0,"קלט לא תקין",IF(ISBLANK(E14),"",IF(OR(E14="כלול",E14="לא רלוונטי"),0,IF(NOT(ISNUMBER(E14)),"קלט לא תקין",IF(E14<0,"קלט לא תקין",ROUND(D14*E14,2)))))))) | G14: 6f64ed20-35c0-4c0c-ae0e-6bfddc26600c | H14: item
A15: 11.09 | B15: אספקה והתקנת ארון שירות מטיפוס {טיפוס}, במידות {מידות}, בחלוקה {חלוקה}, מחומרים ובגמר {מפרט}, לרבות פרזול וחיבורים. משטח עליון מתומחר בנפרד בפרק המשטחים. | C15: יח' | F15: =IF(ISBLANK(D15),"",IF(NOT(ISNUMBER(D15)),"קלט לא תקין",IF(D15<0,"קלט לא תקין",IF(ISBLANK(E15),"",IF(OR(E15="כלול",E15="לא רלוונטי"),0,IF(NOT(ISNUMBER(E15)),"קלט לא תקין",IF(E15<0,"קלט לא תקין",ROUND(D15*E15,2)))))))) | G15: e4142fab-622c-4c97-8e40-155fc06a2ee6 | H15: item
B16: מפרט משותף לפלטות שולחן: תשתית {חומר}, גמר עליון ותחתון {מפרט}, קנט {מפרט}, הכנות וחיבור לרגל {מפרט}. כל גודל או טיפוס בתמחור שונה יופיע כסעיף עצמאי. המידות אינן ערכי ברירת מחדל. | G16: c07c12c9-f785-4ac9-ba64-8c3dd32fd7a1 | H16: note
A17: 11.10 | B17: פלטת שולחן מטיפוס {טיפוס א}, במידות {מידות א}, לפי המפרט המשותף, לרבות {תכולת הכנות וחיבור}. | C17: יח' | F17: =IF(ISBLANK(D17),"",IF(NOT(ISNUMBER(D17)),"קלט לא תקין",IF(D17<0,"קלט לא תקין",IF(ISBLANK(E17),"",IF(OR(E17="כלול",E17="לא רלוונטי"),0,IF(NOT(ISNUMBER(E17)),"קלט לא תקין",IF(E17<0,"קלט לא תקין",ROUND(D17*E17,2)))))))) | G17: f6272e14-b96a-4269-8f83-fe57fa052f79 | H17: item
A18: 11.11 | B18: פלטת שולחן מטיפוס {טיפוס ב}, במידות {מידות ב}, לפי המפרט המשותף, לרבות {תכולת הכנות וחיבור}. | C18: יח' | F18: =IF(ISBLANK(D18),"",IF(NOT(ISNUMBER(D18)),"קלט לא תקין",IF(D18<0,"קלט לא תקין",IF(ISBLANK(E18),"",IF(OR(E18="כלול",E18="לא רלוונטי"),0,IF(NOT(ISNUMBER(E18)),"קלט לא תקין",IF(E18<0,"קלט לא תקין",ROUND(D18*E18,2)))))))) | G18: 1d16f450-db46-4817-83ae-c4be601a2593 | H18: item
A19: 11.12 | B19: פלטת שולחן מטיפוס {טיפוס ג}, במידות {מידות ג}, לפי המפרט המשותף, לרבות {תכולת הכנות וחיבור}. | C19: יח' | F19: =IF(ISBLANK(D19),"",IF(NOT(ISNUMBER(D19)),"קלט לא תקין",IF(D19<0,"קלט לא תקין",IF(ISBLANK(E19),"",IF(OR(E19="כלול",E19="לא רלוונטי"),0,IF(NOT(ISNUMBER(E19)),"קלט לא תקין",IF(E19<0,"קלט לא תקין",ROUND(D19*E19,2)))))))) | G19: 1c434242-36b3-40c9-9d75-9f3d2131bdd2 | H19: item
H20: spacer
B21: סיכום חלקי פרק 11 להעברה | F21: =SUM(F4,F5,F6,F7,F8,F9,F13,F14,F15,F17,F18,F19) -> 0 | H21: total

Sheet מסגרות אושי־אושי
A1: 12 | B1: מסגרות אושי־אושי | G1: c88f8c19-50d0-4f8f-bf05-4ec81294ad24 | H1: chapter
A2: סעיף | B2: תיאור עבודה | C2: יח׳ | D2: כמות | E2: מחיר יחידה | F2: סה״כ | H2: columns
B3: עבודות המסגרות כוללות חומרי גלם, חיבורים, עיגון, הכנת שטח, צבע יסוד וגמר, הובלה והרכבה. שני גמרים מאושרים: שחור מט RAL 9005 וזהב מושחר RAL 1036. כל טיפוס מופיע בסעיף נפרד לכל גמר לצורך תמחור; ממלאים רק את הפריטים והגמרים הנדרשים בסניף ואין לחייב את שניהם לאותו רכיב. חתכים, עוביים, עיגון ותלייה לפי תכנון. נגרות, זכוכית ותאורה בסעיפים נפרדים מוחרגות. | G3: ede56674-a0e0-4594-b46c-35708807b906 | H3: note
A4: 12.01 | B4: אספקה והתקנת שלד מסגרות לדלפק {זיהוי}, מפרופילי ברזל {חתך ועובי לפי תכנון}, בגמר שחור מט RAL 9005, בגובה ובחלוקה {מידות}, לרבות עיגון והכנות למעבר תשתיות. נגרות, אריחים ומשטחים בסעיפים נפרדים אינם כלולים. | C4: מ.א. | F4: =IF(ISBLANK(D4),"",IF(NOT(ISNUMBER(D4)),"קלט לא תקין",IF(D4<0,"קלט לא תקין",IF(ISBLANK(E4),"",IF(OR(E4="כלול",E4="לא רלוונטי"),0,IF(NOT(ISNUMBER(E4)),"קלט לא תקין",IF(E4<0,"קלט לא תקין",ROUND(D4*E4,2)))))))) | G4: a91a7af2-dc99-450d-b0f0-e514181f4b96 | H4: item
A5: 12.02 | B5: אספקה והתקנת יחידת מדפי מתכת או מתקן תצוגה {טיפוס}, מפרופילי ברזל ומשטחים {חתכים ועוביים לפי תכנון}, בגמר שחור מט RAL 9005, במידות {מידות}, לרבות תלייה ועיגון {מפרט}. אין לכלול כאן פריט זהה בגמר זהב מושחר המתומחר בסעיף נפרד. | C5: יח' | F5: =IF(ISBLANK(D5),"",IF(NOT(ISNUMBER(D5)),"קלט לא תקין",IF(D5<0,"קלט לא תקין",IF(ISBLANK(E5),"",IF(OR(E5="כלול",E5="לא רלוונטי"),0,IF(NOT(ISNUMBER(E5)),"קלט לא תקין",IF(E5<0,"קלט לא תקין",ROUND(D5*E5,2)))))))) | G5: 6ac9c51a-c10d-4be4-a589-8ecbdee65bc9 | H5: item
A6: 12.03 | B6: אספקה והתקנת מסגרת ברזל לתמיכת פריט {זיהוי}, בגמר שחור מט RAL 9005, במידות ובחתכים {מפרט תכנון}, לרבות עיגון והכנות {פירוט}. הפריט הנתמך מתומחר בנפרד. | C6: יח' | F6: =IF(ISBLANK(D6),"",IF(NOT(ISNUMBER(D6)),"קלט לא תקין",IF(D6<0,"קלט לא תקין",IF(ISBLANK(E6),"",IF(OR(E6="כלול",E6="לא רלוונטי"),0,IF(NOT(ISNUMBER(E6)),"קלט לא תקין",IF(E6<0,"קלט לא תקין",ROUND(D6*E6,2)))))))) | G6: e2972e79-9c46-48b0-90cc-f830e3330095 | H6: item
A7: 12.04 | B7: אספקה והתקנת מחיצה או מסגרת דקורטיבית מברזל, בגמר שחור מט RAL 9005, באזור {אזור}, במידות, בחתכים ובחלוקה {מפרט תכנון}. מילוי נגרות, אריחים או זכוכית מתומחר בנפרד. | C7: מ"ר | F7: =IF(ISBLANK(D7),"",IF(NOT(ISNUMBER(D7)),"קלט לא תקין",IF(D7<0,"קלט לא תקין",IF(ISBLANK(E7),"",IF(OR(E7="כלול",E7="לא רלוונטי"),0,IF(NOT(ISNUMBER(E7)),"קלט לא תקין",IF(E7<0,"קלט לא תקין",ROUND(D7*E7,2)))))))) | G7: 94c849cd-cf94-40cb-a323-fc827fb7177d | H7: item
A8: 12.05 | B8: אספקה והתקנת מסגרת ברזל תומכת לשילוט בהיקף דלפק {זיהוי}, בגמר שחור מט RAL 9005, במידות ובפרופילים {מפרט תכנון}, לרבות עיגון והכנה למעבר הזנה. אותיות, תאורה ושלט הגמר מתומחרים בנפרד. | C8: מ.א. | F8: =IF(ISBLANK(D8),"",IF(NOT(ISNUMBER(D8)),"קלט לא תקין",IF(D8<0,"קלט לא תקין",IF(ISBLANK(E8),"",IF(OR(E8="כלול",E8="לא רלוונטי"),0,IF(NOT(ISNUMBER(E8)),"קלט לא תקין",IF(E8<0,"קלט לא תקין",ROUND(D8*E8,2)))))))) | G8: 9c0d69cf-954b-4d90-80d9-eef1f2aa6d8a | H8: item
A9: 12.06 | B9: אספקה והתקנת שלד מסגרות לדלפק {זיהוי}, מפרופילי ברזל {חתך ועובי לפי תכנון}, בגמר זהב מושחר RAL 1036, בגובה ובחלוקה {מידות}, לרבות עיגון והכנות למעבר תשתיות. נגרות, אריחים ומשטחים בסעיפים נפרדים אינם כלולים. | C9: מ.א. | F9: =IF(ISBLANK(D9),"",IF(NOT(ISNUMBER(D9)),"קלט לא תקין",IF(D9<0,"קלט לא תקין",IF(ISBLANK(E9),"",IF(OR(E9="כלול",E9="לא רלוונטי"),0,IF(NOT(ISNUMBER(E9)),"קלט לא תקין",IF(E9<0,"קלט לא תקין",ROUND(D9*E9,2)))))))) | G9: be913337-5e8d-4009-8a1b-7543b0addea3 | H9: item
H10: spacer
A11: 12 | B11: מסגרות אושי־אושי (המשך) | H11: heading
A12: סעיף | B12: תיאור עבודה | C12: יח׳ | D12: כמות | E12: מחיר יחידה | F12: סה״כ | H12: columns
A13: 12.07 | B13: אספקה והתקנת יחידת מדפי מתכת או מתקן תצוגה {טיפוס}, מפרופילי ברזל ומשטחים {חתכים ועוביים לפי תכנון}, בגמר זהב מושחר RAL 1036, במידות {מידות}, לרבות תלייה ועיגון {מפרט}. אין לכלול כאן פריט זהה בגמר שחור המתומחר בסעיף נפרד. | C13: יח' | F13: =IF(ISBLANK(D13),"",IF(NOT(ISNUMBER(D13)),"קלט לא תקין",IF(D13<0,"קלט לא תקין",IF(ISBLANK(E13),"",IF(OR(E13="כלול",E13="לא רלוונטי"),0,IF(NOT(ISNUMBER(E13)),"קלט לא תקין",IF(E13<0,"קלט לא תקין",ROUND(D13*E13,2)))))))) | G13: 6d89502a-e2d8-4d8f-8c15-91e7883b0455 | H13: item
A14: 12.08 | B14: אספקה והתקנת מסגרת ברזל לתמיכת פריט {זיהוי}, בגמר זהב מושחר RAL 1036, במידות ובחתכים {מפרט תכנון}, לרבות עיגון והכנות {פירוט}. הפריט הנתמך מתומחר בנפרד. | C14: יח' | F14: =IF(ISBLANK(D14),"",IF(NOT(ISNUMBER(D14)),"קלט לא תקין",IF(D14<0,"קלט לא תקין",IF(ISBLANK(E14),"",IF(OR(E14="כלול",E14="לא רלוונטי"),0,IF(NOT(ISNUMBER(E14)),"קלט לא תקין",IF(E14<0,"קלט לא תקין",ROUND(D14*E14,2)))))))) | G14: 98ed4f35-d46a-47fc-b06a-06e1cbf28e04 | H14: item
A15: 12.09 | B15: אספקה והתקנת מחיצה או מסגרת דקורטיבית מברזל, בגמר זהב מושחר RAL 1036, באזור {אזור}, במידות, בחתכים ובחלוקה {מפרט תכנון}. מילוי נגרות, אריחים או זכוכית מתומחר בנפרד. | C15: מ"ר | F15: =IF(ISBLANK(D15),"",IF(NOT(ISNUMBER(D15)),"קלט לא תקין",IF(D15<0,"קלט לא תקין",IF(ISBLANK(E15),"",IF(OR(E15="כלול",E15="לא רלוונטי"),0,IF(NOT(ISNUMBER(E15)),"קלט לא תקין",IF(E15<0,"קלט לא תקין",ROUND(D15*E15,2)))))))) | G15: a02b0c22-f069-471d-aac4-106aec900ad0 | H15: item
A16: 12.10 | B16: אספקה והתקנת מסגרת ברזל תומכת לשילוט בהיקף דלפק {זיהוי}, בגמר זהב מושחר RAL 1036, במידות ובפרופילים {מפרט תכנון}, לרבות עיגון והכנה למעבר הזנה. אותיות, תאורה ושלט הגמר מתומחרים בנפרד. | C16: מ.א. | F16: =IF(ISBLANK(D16),"",IF(NOT(ISNUMBER(D16)),"קלט לא תקין",IF(D16<0,"קלט לא תקין",IF(ISBLANK(E16),"",IF(OR(E16="כלול",E16="לא רלוונטי"),0,IF(NOT(ISNUMBER(E16)),"קלט לא תקין",IF(E16<0,"קלט לא תקין",ROUND(D16*E16,2)))))))) | G16: 7bc1bad8-a136-40ed-a037-d1a04cc009a2 | H16: item
H17: spacer
B18: סיכום חלקי פרק 12 להעברה | F18: =SUM(F4,F5,F6,F7,F8,F9,F13,F14,F15,F16) -> 0 | H18: total

Sheet אלומיניום וזיגוג אושי־אושי
A1: 13 | B1: אלומיניום וזיגוג אושי־אושי | G1: db68935b-099f-4748-8872-86df3c0cdc54 | H1: chapter
A2: סעיף | B2: תיאור עבודה | C2: יח׳ | D2: כמות | E2: מחיר יחידה | F2: סה״כ | H2: columns
B3: כל טיפוס פתח או זיגוג יפורט לפי מידות, שימוש, פרופיל, סוג ועובי זכוכית, פרזול וגמר. אין ברירת מחדל לסדרת פרופיל, עובי זכוכית או שיטת עיגון. רכיב מתומחר כאן לא ייכלל שוב במפרט נגרות או מסגרות. | G3: 1ea82966-c69b-4c57-ab84-7be26dd80dd7 | H3: note
A4: 13.01 | B4: אספקה והתקנת חלון, דלת או ויטרינה מטיפוס {זיהוי}, במידות {מידות}. סוג פתיחה וחלוקה: {מפרט}; פרופיל וגמר: {מפרט}; זיגוג: {סוג ועובי}; פרזול, אטימה וסיומות: {מפרט}; פרט: {הפניה}. | C4: יח' | F4: =IF(ISBLANK(D4),"",IF(NOT(ISNUMBER(D4)),"קלט לא תקין",IF(D4<0,"קלט לא תקין",IF(ISBLANK(E4),"",IF(OR(E4="כלול",E4="לא רלוונטי"),0,IF(NOT(ISNUMBER(E4)),"קלט לא תקין",IF(E4<0,"קלט לא תקין",ROUND(D4*E4,2)))))))) | G4: 99cb4301-2cf4-4688-afe7-32f8d8fbde3d | H4: item
A5: 13.02 | B5: אספקה והתקנת לוח זיגוג מטיפוס {זיהוי}, במידות {מידות}, בסוג ובעובי {מפרט}, לרבות חיבורים ופרזול שנקבעו לפרט. שלד המסגרת מתומחר בנפרד ככל שהוגדר בפרק המסגרות. | C5: יח' | F5: =IF(ISBLANK(D5),"",IF(NOT(ISNUMBER(D5)),"קלט לא תקין",IF(D5<0,"קלט לא תקין",IF(ISBLANK(E5),"",IF(OR(E5="כלול",E5="לא רלוונטי"),0,IF(NOT(ISNUMBER(E5)),"קלט לא תקין",IF(E5<0,"קלט לא תקין",ROUND(D5*E5,2)))))))) | G5: fefbffb3-a85b-4be5-9251-ca172d4de6bf | H5: item
A6: 13.03 | B6: אספקה והתקנת מראה מטיפוס {זיהוי}, במידות ובצורה {מידות}, בסוג ובעובי {מפרט}, עם גמר קצה וחיבור {פירוט}. מסגרת ותאורה נכללות רק אם צוינו במפורש. | C6: יח' | F6: =IF(ISBLANK(D6),"",IF(NOT(ISNUMBER(D6)),"קלט לא תקין",IF(D6<0,"קלט לא תקין",IF(ISBLANK(E6),"",IF(OR(E6="כלול",E6="לא רלוונטי"),0,IF(NOT(ISNUMBER(E6)),"קלט לא תקין",IF(E6<0,"קלט לא תקין",ROUND(D6*E6,2)))))))) | G6: c4175152-e8a6-406f-8bda-4c454e4f5583 | H6: item
H7: spacer
B8: סיכום חלקי פרק 13 להעברה | F8: =SUM(F4,F5,F6) -> 0 | H8: total

Sheet משטחים מיוחדים
A1: 14 | B1: משטחים מיוחדים | G1: c69dceb1-4be0-4306-a4d6-cee141b1b67c | H1: chapter
A2: סעיף | B2: תיאור עבודה | C2: יח׳ | D2: כמות | E2: מחיר יחידה | F2: סה״כ | H2: columns
B3: מחירי המשטחים כוללים עיבוד, חיתוכים, פתחים, קנטים, הובלה והרכבה רק כפי שהוגדרו בפריט. חומר, דגם, עובי וחתך הם משתני פרויקט. אותו משטח לא ייכלל שוב במחיר הנגרות או הציוד. | G3: 0211a3d5-ce4e-46cb-82c0-2b1d9cfa8562 | H3: note
A4: 14.01 | B4: אספקה והתקנת משטח עבודה עבור {פריט}, מחומר ודגם {מפרט}, ברוחב ובעובי {מידות}, לרבות פתחים, קנטים וחיבורים {פירוט}, על תשתית {סוג}. | C4: מ.א. | F4: =IF(ISBLANK(D4),"",IF(NOT(ISNUMBER(D4)),"קלט לא תקין",IF(D4<0,"קלט לא תקין",IF(ISBLANK(E4),"",IF(OR(E4="כלול",E4="לא רלוונטי"),0,IF(NOT(ISNUMBER(E4)),"קלט לא תקין",IF(E4<0,"קלט לא תקין",ROUND(D4*E4,2)))))))) | G4: 4e57bc45-072e-4150-b60e-fd86cf1d2ef8 | H4: item
A5: 14.02 | B5: אספקה והתקנת קופינג או צוקל לדלפק או למחיצה {זיהוי}, מחומר ודגם {מפרט}, בחתך {מידות}, עם פינות, קנטים וחיבורים {פירוט}. | C5: מ.א. | F5: =IF(ISBLANK(D5),"",IF(NOT(ISNUMBER(D5)),"קלט לא תקין",IF(D5<0,"קלט לא תקין",IF(ISBLANK(E5),"",IF(OR(E5="כלול",E5="לא רלוונטי"),0,IF(NOT(ISNUMBER(E5)),"קלט לא תקין",IF(E5<0,"קלט לא תקין",ROUND(D5*E5,2)))))))) | G5: 83e364dc-1b36-4b81-a311-5d68d8e524f2 | H5: item
A6: 14.03 | B6: אספקה והתקנת משטח כיור לארון {זיהוי}, במידות {מידות}, מחומר ודגם {מפרט}, עם פתחים, קנטים וחיבור {פירוט}. כיור וברז: {כלולים או מוחרגים במפורש}. | C6: יח' | F6: =IF(ISBLANK(D6),"",IF(NOT(ISNUMBER(D6)),"קלט לא תקין",IF(D6<0,"קלט לא תקין",IF(ISBLANK(E6),"",IF(OR(E6="כלול",E6="לא רלוונטי"),0,IF(NOT(ISNUMBER(E6)),"קלט לא תקין",IF(E6<0,"קלט לא תקין",ROUND(D6*E6,2)))))))) | G6: 11c7765a-0e84-4cbf-89f1-f330a0932a0f | H6: item
H7: spacer
H8: spacer
B9: סיכום חלקי פרק 14 להעברה | F9: =SUM(F4,F5,F6) -> 0 | H9: total

Sheet אספקות גמר נפרדות
A1: 15 | B1: אספקות גמר נפרדות | G1: 6114ed4a-0542-455f-a7ed-1f5a61b2a057 | H1: chapter
A2: סעיף | B2: תיאור עבודה | C2: יח׳ | D2: כמות | E2: מחיר יחידה | F2: סה״כ | H2: columns
B3: פרק אספקות נפתח רק כשהאספקה נפרדת מהתקנה. מפרטי האריחים, הגוונים והגמרים בשורות הרשת חלים גם על האספקה המקבילה; אין לפתוח שוב בחירה חופשית במקום מפרט שנקבע. במקורות אין דגם גוף תאורה משותף ומלא לרשת: OS-08. כל טיפוס אספקה בעל תמחור שונה יקבל סעיף עצמאי. אין כמויות רכש או פחת בתבנית. | G3: 05e0039a-1dac-4677-95a7-679d514b9228 | H3: note
A4: 15.01 | B4: אספקת אריחי ריצוף או חיפוי מטיפוס {זיהוי}, מחומר ודגם {מפרט}, במידה ובגמר {מפרט}. הובלה ופריקה: {תכולה}; התקנה מתומחרת בנפרד. | C4: מ"ר | F4: =IF(ISBLANK(D4),"",IF(NOT(ISNUMBER(D4)),"קלט לא תקין",IF(D4<0,"קלט לא תקין",IF(ISBLANK(E4),"",IF(OR(E4="כלול",E4="לא רלוונטי"),0,IF(NOT(ISNUMBER(E4)),"קלט לא תקין",IF(E4<0,"קלט לא תקין",ROUND(D4*E4,2)))))))) | G4: d79791c7-a25c-413d-af24-d032985ea078 | H4: item
A5: 15.02 | B5: אספקת כלי או אביזר סניטרי מטיפוס {זיהוי}, בדגם ובגמר {מפרט}, לרבות {אביזרים נלווים}. התקנה וחיבור מתומחרים בפרק האינסטלציה. | C5: יח' | F5: =IF(ISBLANK(D5),"",IF(NOT(ISNUMBER(D5)),"קלט לא תקין",IF(D5<0,"קלט לא תקין",IF(ISBLANK(E5),"",IF(OR(E5="כלול",E5="לא רלוונטי"),0,IF(NOT(ISNUMBER(E5)),"קלט לא תקין",IF(E5<0,"קלט לא תקין",ROUND(D5*E5,2)))))))) | G5: 41ea2e75-51bf-4b18-86a4-c3a2d83568a1 | H5: item
A6: 15.03 | B6: אספקת גוף תאורה מטיפוס {זיהוי}, במפרט ובדגם {מפרט}, עם {ספק, דרייבר ואביזרים נלווים לפי הנדרש}. התקנה ונקודת הזנה מתומחרות בפרק החשמל. | C6: יח' | F6: =IF(ISBLANK(D6),"",IF(NOT(ISNUMBER(D6)),"קלט לא תקין",IF(D6<0,"קלט לא תקין",IF(ISBLANK(E6),"",IF(OR(E6="כלול",E6="לא רלוונטי"),0,IF(NOT(ISNUMBER(E6)),"קלט לא תקין",IF(E6<0,"קלט לא תקין",ROUND(D6*E6,2)))))))) | G6: f7ba6162-7a3c-409e-9652-9d29de9cd080 | H6: item
H7: spacer
B8: סיכום חלקי פרק 15 להעברה | F8: =SUM(F4,F5,F6) -> 0 | H8: total

Sheet מיזוג ואוורור
A1: 16 | B1: מיזוג ואוורור | G1: f66b1b6b-82c7-4ecf-89c7-694d49025855 | H1: chapter
A2: סעיף | B2: תיאור עבודה | C2: יח׳ | D2: כמות | E2: מחיר יחידה | F2: סה״כ | H2: columns
B3: תוכן מערכת זו יושלם בפרויקט לפי תכנון היועץ ורשימת הציוד המאושרים. שורות התבנית מגדירות גבולות תכולה ואינן מפרט הנדסי מלא. אין להסיק מהפעלת הפרק שהמערכת נדרשת בכל אתר. | G3: a6b1da0d-28be-4b30-939d-973a7d8c8ccf | H3: note
A4: 16.01 | B4: ביצוע מערכת מיזוג ואוורור בתכולת {מערכת מוגדרת}, לפי תכנון {הפניה}, לרבות {אספקה, התקנה, חיבור והפעלה}. גבולות מול חשמל, ניקוז ותקרות: {פירוט}. | C4: קומפ' | F4: =IF(ISBLANK(D4),"",IF(NOT(ISNUMBER(D4)),"קלט לא תקין",IF(D4<0,"קלט לא תקין",IF(ISBLANK(E4),"",IF(OR(E4="כלול",E4="לא רלוונטי"),0,IF(NOT(ISNUMBER(E4)),"קלט לא תקין",IF(E4<0,"קלט לא תקין",ROUND(D4*E4,2)))))))) | G4: 4430e329-d945-41f7-a764-feb500d143c7 | H4: item
H5: spacer
H6: spacer
B7: סיכום חלקי פרק 16 להעברה | F7: =SUM(F4) -> 0 | H7: total

Sheet ציוד מטבח ונירוסטה
A1: 17 | B1: ציוד מטבח ונירוסטה | G1: 271c19a0-eccc-4801-a1e3-45ed2d1f81f9 | H1: chapter
A2: סעיף | B2: תיאור עבודה | C2: יח׳ | D2: כמות | E2: מחיר יחידה | F2: סה״כ | H2: columns
B3: תוכן מערכת זו יושלם בפרויקט לפי תכנון היועץ ורשימת הציוד המאושרים. שורות התבנית מגדירות גבולות תכולה ואינן מפרט הנדסי מלא. אין להסיק מהפעלת הפרק שהמערכת נדרשת בכל אתר. | G3: bebd7028-32ab-4e90-9cae-d17a27cbacdc | H3: note
A4: 17.01 | B4: אספקה והתקנת פריט ציוד מטבח או נירוסטה {זיהוי}, לפי רשימת ציוד {הפניה}, בתכולת {מפרט}, עם גבולות חיבור למערכות {פירוט}. | C4: יח' | F4: =IF(ISBLANK(D4),"",IF(NOT(ISNUMBER(D4)),"קלט לא תקין",IF(D4<0,"קלט לא תקין",IF(ISBLANK(E4),"",IF(OR(E4="כלול",E4="לא רלוונטי"),0,IF(NOT(ISNUMBER(E4)),"קלט לא תקין",IF(E4<0,"קלט לא תקין",ROUND(D4*E4,2)))))))) | G4: bd805dde-5240-4b77-ad6f-adb0d8432d13 | H4: item
H5: spacer
H6: spacer
B7: סיכום חלקי פרק 17 להעברה | F7: =SUM(F4) -> 0 | H7: total

Sheet הכנות ומערכת גז
A1: 18 | B1: הכנות ומערכת גז | G1: 6242246f-f711-4c70-a8a1-f1b154b12de4 | H1: chapter
A2: סעיף | B2: תיאור עבודה | C2: יח׳ | D2: כמות | E2: מחיר יחידה | F2: סה״כ | H2: columns
B3: מערכת הגז נפתחת רק כשנדרשת בתכנון הפרויקט. תשתית, אביזרים, בדיקות וגבולות חיבור ייקבעו במפרט המתכנן והגורם המבצע; אין הנחת סוג צנרת, צובר קיים או מיקום ציוד מהארכיון. | G3: cf1f2c8b-f851-4583-bee3-355c9d5508ff | H3: note
A4: 18.01 | B4: ביצוע נקודת גז עבור {ציוד מזוהה}, לפי תכנון {הפניה}, לרבות התשתית ואביזרי החיבור בתכולת {מפרט}. גבולות אחריות אספקת המערכת, חיבור הציוד ובדיקות: {פירוט}. | C4: נק' | F4: =IF(ISBLANK(D4),"",IF(NOT(ISNUMBER(D4)),"קלט לא תקין",IF(D4<0,"קלט לא תקין",IF(ISBLANK(E4),"",IF(OR(E4="כלול",E4="לא רלוונטי"),0,IF(NOT(ISNUMBER(E4)),"קלט לא תקין",IF(E4<0,"קלט לא תקין",ROUND(D4*E4,2)))))))) | G4: f37a71cd-2251-46bf-a7f4-f9a14e3dbe6f | H4: item
H5: spacer
H6: spacer
B7: סיכום חלקי פרק 18 להעברה | F7: =SUM(F4) -> 0 | H7: total

Sheet כיבוי וגילוי
A1: 19 | B1: כיבוי וגילוי | G1: 16cc9239-2691-4917-b952-d47f6582819f | H1: chapter
A2: סעיף | B2: תיאור עבודה | C2: יח׳ | D2: כמות | E2: מחיר יחידה | F2: סה״כ | H2: columns
B3: תוכן מערכת זו יושלם בפרויקט לפי תכנון היועץ ורשימת הציוד המאושרים. שורות התבנית מגדירות גבולות תכולה ואינן מפרט הנדסי מלא. אין להסיק מהפעלת הפרק שהמערכת נדרשת בכל אתר. | G3: 080669c8-5251-411c-a0cf-4d05eaf25115 | H3: note
A4: 19.01 | B4: ביצוע מערכת כיבוי {סוג מערכת מוגדר}, לפי תכנון בטיחות וכיבוי {הפניה}, בגבולות {תכולה ואחריות}, עם הממשקים למערכות האחרות כמפורט. | C4: קומפ' | F4: =IF(ISBLANK(D4),"",IF(NOT(ISNUMBER(D4)),"קלט לא תקין",IF(D4<0,"קלט לא תקין",IF(ISBLANK(E4),"",IF(OR(E4="כלול",E4="לא רלוונטי"),0,IF(NOT(ISNUMBER(E4)),"קלט לא תקין",IF(E4<0,"קלט לא תקין",ROUND(D4*E4,2)))))))) | G4: 3d054596-1420-40d4-a88b-ed47366d45f6 | H4: item
A5: 19.02 | B5: ביצוע מערכת גילוי או התרעה {סוג מערכת מוגדר}, לפי תכנון {הפניה}, בגבולות {תכולה ואחריות}, עם ההכנות והחיבורים המפורטים. | C5: קומפ' | F5: =IF(ISBLANK(D5),"",IF(NOT(ISNUMBER(D5)),"קלט לא תקין",IF(D5<0,"קלט לא תקין",IF(ISBLANK(E5),"",IF(OR(E5="כלול",E5="לא רלוונטי"),0,IF(NOT(ISNUMBER(E5)),"קלט לא תקין",IF(E5<0,"קלט לא תקין",ROUND(D5*E5,2)))))))) | G5: 107122bc-7559-4a35-aa88-0f04c5ac4ced | H5: item
H6: spacer
H7: spacer
B8: סיכום חלקי פרק 19 להעברה | F8: =SUM(F4,F5) -> 0 | H8: total

Sheet אביזרי נגישות
A1: 20 | B1: אביזרי נגישות | G1: 08aadde9-c0a6-438e-a608-b7f230bf1427 | H1: chapter
A2: סעיף | B2: תיאור עבודה | C2: יח׳ | D2: כמות | E2: מחיר יחידה | F2: סה״כ | H2: columns
B3: אביזרי נגישות יוגדרו לפי תכנון הנגישות בפרויקט. אין להעתיק מידות, מיקום או רשימת אביזרים מתיק אחר. האביזרים אינם כלולים שוב במחיר מכל ההדחה או הנגרות. | G3: 48aa3c72-d099-44cc-94af-690fe47fbbf6 | H3: note
A4: 20.01 | B4: אספקה והתקנת ערכת אביזרי נגישות לחדר שירות {זיהוי}, הכוללת {רשימה מאושרת של אביזרים}, בחומרים, במידות ובמיקומים לפי תכנון {הפניה}, לרבות העיגון המוגדר. | C4: יח' | F4: =IF(ISBLANK(D4),"",IF(NOT(ISNUMBER(D4)),"קלט לא תקין",IF(D4<0,"קלט לא תקין",IF(ISBLANK(E4),"",IF(OR(E4="כלול",E4="לא רלוונטי"),0,IF(NOT(ISNUMBER(E4)),"קלט לא תקין",IF(E4<0,"קלט לא תקין",ROUND(D4*E4,2)))))))) | G4: bff4b214-9be8-46d8-849c-8aea60c0700f | H4: item
H5: spacer
H6: spacer
B7: סיכום חלקי פרק 20 להעברה | F7: =SUM(F4) -> 0 | H7: total

Sheet שילוט ומיתוג
A1: 21 | B1: שילוט ומיתוג | G1: 500fce2c-0b40-4874-945f-b08548d24364 | H1: chapter
A2: סעיף | B2: תיאור עבודה | C2: יח׳ | D2: כמות | E2: מחיר יחידה | F2: סה״כ | H2: columns
B3: תוכן מערכת זו יושלם בפרויקט לפי תכנון היועץ ורשימת הציוד המאושרים. שורות התבנית מגדירות גבולות תכולה ואינן מפרט הנדסי מלא. אין להסיק מהפעלת הפרק שהמערכת נדרשת בכל אתר. | G3: 7427a35d-c54b-4cac-8b50-59f437a2794d | H3: note
A4: 21.01 | B4: אספקה והתקנת שילוט או אותיות מטיפוס {זיהוי}, במידות ובחומר {מפרט}, בגמר {גמר}, לרבות {תאורה, ספק, פרזול והתקנה}. תשתית והזנה מתומחרות בנפרד אם צוינו בפרק החשמל. | C4: יח' | F4: =IF(ISBLANK(D4),"",IF(NOT(ISNUMBER(D4)),"קלט לא תקין",IF(D4<0,"קלט לא תקין",IF(ISBLANK(E4),"",IF(OR(E4="כלול",E4="לא רלוונטי"),0,IF(NOT(ISNUMBER(E4)),"קלט לא תקין",IF(E4<0,"קלט לא תקין",ROUND(D4*E4,2)))))))) | G4: 91ab0439-3352-4b64-a5ca-14e972a80379 | H4: item
H5: spacer
H6: spacer
B7: סיכום חלקי פרק 21 להעברה | F7: =SUM(F4) -> 0 | H7: total

Sheet ריהוט וישיבה
A1: 22 | B1: ריהוט וישיבה | G1: 38398255-8c0d-429c-bcac-98b4a88d3016 | H1: chapter
